Workbook

Sheet Dữ liệu thô
A1: Mã đơn hàng | B1: Ngày đặt hàng | C1: Mã KH | D1: Tên khách hàng | E1: Phân khúc | F1: Khu vực | G1: Tỉnh/Thành | H1: Danh mục | I1: Sản phẩm | J1: Kênh bán | K1: Nhân viên bán hàng | L1: Số lượng | M1: Đơn giá (VNĐ) | N1: Giảm giá | O1: Giá vốn đơn vị (VNĐ) | P1: Trạng thái | R1: Chú thích màu
A2: DH2025-0001 | B2: 05/01/2025 | C2: KH040 | D2: Bùi Minh An | E2: Cá nhân | F2: Miền Bắc | G2: Quảng Ninh | H2: Mỹ phẩm | I2: Serum Vitamin C | J2: Website | K2: Trần Quốc Bảo | L2: 2 | M2: 588000 | N2: 0.15 | O2: 260000 | P2: Hoàn thành | R2: Ô vàng: ô có lỗi định dạng / thiếu giá trị
A3: DH2025-0002 | B3: 45666 | C3: KH040 | D3: Bùi Minh An | E3: Cá nhân | F3: Miền Bắc | G3: Quảng Ninh | H3: Mỹ phẩm | I3: Son lì | J3: Website | K3: Phạm Đức Huy | L3: 3 | M3: 290000 | N3: 0.1 | O3: 120000 | P3: Hoàn thành | R3: Dòng đỏ: dòng bị nhân đôi (trùng Mã đơn hàng)
A4: DH2025-0003 | B4: 45667 | C4: KH046 | D4: Phan Minh Khoa | E4: Cá nhân | F4: Miền Bắc | G4: Quảng Ninh | H4: Điện tử | I4: Tai nghe Bluetooth | J4: Sàn TMĐT | K4: Lê Thu Hà | L4: 1 | M4: 892000 | N4: 0.2 | O4: 520000 | P4: Hoàn trả | R4: Dữ liệu mô phỏng, được cố ý chèn lỗi để minh họa bước làm sạch.
A5: DH2025-0004 | B5: 45669 | C5: KH043 | D5: Phạm Hoàng Giang | E5: Cá nhân | F5: Miền Trung | G5: Huế | H5: Gia dụng | I5: Ấm siêu tốc | J5: Sàn TMĐT | K5: Trần Quốc Bảo | L5: 1 | M5: 520000 | N5: 0 | O5: 310000 | P5: Hoàn thành
A6: DH2025-0005 | B6: 45670 | C6: KH008 | D6: Hoàng Đức Trang | E6: Cá nhân | F6: Miền Nam | G6: Bình Dương | H6: Thực phẩm | I6: Trà thảo mộc hộp | J6: Cửa hàng | K6: Trần Quốc Bảo | L6: 1 | M6: 200000 | N6: 0 | O6: 120000 | P6: Hoàn thành
A7: DH2025-0006 | B7: 45674 | C7: KH008 | D7: Hoàng Đức Trang | E7: Cá nhân | F7: Miền Nam | G7: Bình Dương | H7: Điện tử | I7: Loa thông minh | J7: Website | K7: Nguyễn Minh Anh | L7: 1 | M7: 1900000 | N7: 0 | O7: 1200000 | P7: Hoàn thành
A8: DH2025-0007 | B8: 45676 | C8: KH051 | D8: Đỗ Minh Long | E8: Cá nhân | F8: Miền Bắc | G8: Bắc Ninh | H8: Thực phẩm | I8: Hạt dinh dưỡng mix | J8: Website | K8: Bùi Thanh Tùng | L8: 1 | M8: 340000 | N8: 0 | O8: 220000 | P8: Hoàn thành
A9: DH2025-0008 | B9: 45676 | C9: KH048 | D9: Phạm Thị Quân | E9: Cá nhân | F9: Miền Bắc | G9: Hải Phòng | H9: Thực phẩm | I9: Cà phê rang xay 1kg | J9: Cửa hàng | K9: Võ Ngọc Lan | L9: 1 | M9: 380000 | N9: 0.05 | O9: 250000 | P9: Hoàn thành
A10: DH2025-0009 | B10: 45678 | C10: KH054 | D10: Phan Hoàng Bình | E10: Cá nhân | F10: Miền Trung | G10: Khánh Hòa | H10: Thời trang | I10: Giày thể thao | K10: Lê Thu Hà | L10: 1 | M10: 1500000 | N10: 0.2 | O10: 800000 | P10: Hoàn thành
A11: DH2025-0010 | B11: 45678 | C11: KH011 | D11: Công ty CP Bình Minh | E11: Doanh nghiệp | F11: Miền Bắc | G11: Quảng Ninh | H11: Thời trang | I11: Áo khoác gió | J11: Đại lý | K11: Võ Ngọc Lan | L11: 8 | M11: 750000 | N11: 0.05 | O11: 390000 | P11: Đã hủy
A12: DH2025-0011 | B12: 45679 | C12: KH031 | D12: Vũ Đức Hà | E12: Cá nhân | F12: Miền Nam | G12: Cần Thơ | H12: Thời trang | I12: Túi xách nữ | J12: Website | K12: Nguyễn Minh Anh | L12: 1 | M12: 1140000 | N12: 10 | O12: 620000 | P12: Hoàn thành
A13: DH2025-0012 | B13: 45681 | C13: KH056 | D13: Lê Anh Mai | E13: Cá nhân | F13: Miền Nam | G13: Đồng Nai | H13: Mỹ phẩm | I13: Serum Vitamin C | J13: Website | K13: Đặng Hoàng Nam | L13: 2 | M13: 588000 | N13: 0.1 | O13: 260000 | P13: Hoàn thành
A14: DH2025-0013 | B14: 24/01/2025 | C14: KH040 | D14: Bùi Minh An | E14: Cá nhân | F14: Miền Bắc | G14: Quảng Ninh | H14: Gia dụng | I14: Ấm siêu tốc | J14: Website | K14: Võ Ngọc Lan | L14: 1 | M14: 520000 | N14: 0 | O14: 310000 | P14: Đã hủy
A15: DH2025-0014 | B15: 45684 | C15: KH055 | D15: Công ty CP Sao Việt | E15: Doanh nghiệp | F15: Miền Nam | G15: Bình Dương | H15: Điện tử | I15: Tai nghe Bluetooth | J15: Đại lý | K15: Nguyễn Minh Anh | L15: 3 | M15: 808000 | N15: 0.1 | O15: 520000 | P15: Hoàn thành
A16: DH2025-0015 | B16: 45685 | C16: KH057 | D16: Huỳnh Thu Hải | E16: Cá nhân | F16: Miền Nam | G16: Bình Dương | H16: Thời trang | I16: Áo khoác gió | J16: Sàn TMĐT | K16: Võ Ngọc Lan | L16: 1 | M16: 750000 | N16: 0 | O16: 390000 | P16: Hoàn thành
A17: DH2025-0016 | B17: 45685 | C17: KH043 | D17: Phạm Hoàng Giang | E17: Cá nhân | F17: Miền Trung | G17: Huế | H17: Thực phẩm | I17: Hạt dinh dưỡng mix | J17: Cửa hàng | K17: Võ Ngọc Lan | L17: 4 | M17: 340000 | N17: 0.15 | O17: 220000 | P17: Hoàn thành
A18: DH2025-0017 | B18: 01/02/2025 | C18: KH013 | D18: Phan Đức Tuấn | E18: Cá nhân | F18: Miền Nam | G18: Cần Thơ | H18: Thời trang | I18: Áo thun nam | J18: Sàn TMĐT | K18: Trần Quốc Bảo | L18: 1 | M18: 294000 | N18: 0.2 | O18: 130000 | P18: Hoàn thành
A19: DH2025-0018 | B19: 45699 | C19: KH034 | D19: Nguyễn Quốc Dũng | E19: Cá nhân | F19: Miền Nam | G19: Bình Dương | H19: Thời trang | I19: Túi xách nữ | J19: Website | L19: 4 | M19: 1200000 | N19: 0.05 | O19: 620000 | P19: Hoàn thành
A20: DH2025-0019 | B20: 45700 | C20: KH010 | D20: Phan Thị Dũng | E20: Cá nhân | F20: Miền Trung | G20: Khánh Hòa | H20: Mỹ phẩm | I20: Kem chống nắng | J20: Sàn TMĐT | K20: Bùi Thanh Tùng | L20: 1 | M20: 320000 | N20: 0 | O20: 150000 | P20: Hoàn thành
A21: DH2025-0020 | B21: 45705 | C21: KH001 | D21: Phan Ngọc Quân | E21: Cá nhân | F21: Miền Trung | G21: Nghệ An | H21: Điện tử | I21: Sạc dự phòng 20000mAh | K21: Bùi Thanh Tùng | L21: 1 | M21: 690000 | N21: 0.05 | O21: 410000 | P21: Hoàn thành
A22: DH2025-0021 | B22: 45712 | C22: KH020 | D22: Hoàng Hoàng Long | E22: Cá nhân | F22: Miền Nam | G22: TP. Hồ Chí Minh | H22: Điện tử | I22: Bàn phím cơ | J22: Cửa hàng | K22: Lê Thu Hà | L22: 4 | M22: 1200000 | N22: 0.15 | O22: 720000 | P22: Hoàn thành
A23: DH2025-0022 | B23: 45718 | C23: KH052 | D23: Vũ Thanh Châu | E23: Cá nhân | F23: Miền Nam | G23: Bình Dương | H23: Gia dụng | I23: Máy hút bụi mini | J23: Website | K23: Lê Thu Hà | L23: 4 | M23: 1600000 | N23: 0.2 | O23: 1000000 | P23: Hoàn thành
A24: DH2025-0023 | B24: 45719 | C24: KH009 | D24: Cửa hàng Tân Tiến | E24: Doanh nghiệp | F24: Miền Bắc | G24: Quảng Ninh | H24: Gia dụng | I24: Máy hút bụi mini | J24: Đại lý | K24: Đặng Hoàng Nam | L24: 6 | M24: 1520000 | N24: 0 | O24: 1000000 | P24: Hoàn thành
A25: DH2025-0024 | B25: 03/03/2025 | C25: KH039 | D25: Võ Thanh Hải | E25: Cá nhân | F25: Miền Bắc | G25: Bắc Ninh | H25: Mỹ phẩm | I25: Serum Vitamin C | J25: Sàn TMĐT | K25: Võ Ngọc Lan | L25: 1 | M25: 560000 | N25: 0.15 | O25: 260000 | P25: Hoàn thành
A26: DH2025-0025 | B26: 45722 | C26: KH036 | D26: Hoàng Thị Phúc | E26: Cá nhân | F26: Miền Bắc | G26: Bắc Ninh | H26: Thực phẩm | I26: Trà thảo mộc hộp | J26: Sàn TMĐT | K26: Võ Ngọc Lan | L26: 3 | M26: 210000 | N26: 0 | O26: 120000 | P26: Hoàn thành
A27: DH2025-0026 | B27: 45722 | C27: KH025 | D27: Phạm Minh Phúc | E27: Cá nhân | F27: Miền Bắc | G27: Bắc Ninh | H27: Mỹ phẩm | I27: Kem chống nắng | J27: Cửa hàng | K27: Nguyễn Minh Anh | L27: 2 | M27: 320000 | N27: 0 | O27: 150000 | P27: Hoàn thành
A28: DH2025-0027 | B28: 45725 | C28: KH056 | D28: Lê Anh Mai | E28: Cá nhân | F28: Miền Nam | G28: Đồng Nai | H28: Thời trang | I28: Túi xách nữ | J28: Website | K28: Bùi Thanh Tùng | L28: 1 | M28: 1200000 | N28: 0.1 | O28: 620000 | P28: Hoàn thành
A29: DH2025-0028 | B29: 45728 | C29: KH049 | D29: Phan Anh Quân | E29: Cá nhân | F29: Miền Bắc | G29: Bắc Ninh | H29: Điện tử | I29: Loa thông minh | J29: Cửa hàng | K29: Hoàng Mai Linh | L29: 1 | M29: 1805000 | N29: 0 | O29: 1200000 | P29: Hoàn thành
A30: DH2025-0029 | B30: 45728 | C30: KH028 | D30: Công ty TNHH Lạc Hồng | E30: Doanh nghiệp | F30: Miền Nam | G30: TP. Hồ Chí Minh | H30: Thời trang | I30: Áo thun nam | J30: Cửa hàng | K30: Võ Ngọc Lan | L30: 5 | M30: 280000 | N30: 15 | O30: 130000 | P30: Hoàn trả
A31: DH2025-0030 | B31: 45728 | C31: KH007 | D31: Công ty TNHH An Phát | E31: Doanh nghiệp | F31: Miền Nam | G31: Cần Thơ | H31: Điện tử | I31: Loa thông minh | J31: Website | K31: Hoàng Mai Linh | L31: 5 | M31: 1900000 | N31: 0.15 | O31: 1200000 | P31: Hoàn thành
A32: DH2025-0031 | B32: 45730 | C32: KH032 | D32: Nguyễn Hoàng Dũng | E32: Cá nhân | F32: Miền Trung | G32: Khánh Hòa | H32: Mỹ phẩm | I32: Kem chống nắng | J32: Cửa hàng | K32: Trần Quốc Bảo | L32: 1 | M32: 304000 | N32: 0 | O32: 150000 | P32: Hoàn thành
A33: DH2025-0032 | B33: 45737 | C33: KH054 | D33: Phan Hoàng Bình | E33: Cá nhân | F33: Miền Trung | G33: Khánh Hòa | H33: Điện tử | I33: Bàn phím cơ | J33: Website | K33: Phạm Đức Huy | L33: 2 | M33: 1260000 | N33: 0 | O33: 720000 | P33: Hoàn thành
A34: DH2025-0033 | B34: 45737 | C34: KH044 | D34: Công ty TNHH Đại Dương | E34: Doanh nghiệp | F34: Miền Bắc | G34: Hà Nội | H34: Thực phẩm | I34: Trà thảo mộc hộp | J34: Đại lý | K34: Hoàng Mai Linh | L34: 2 | M34: 210000 | N34: 0.1 | O34: 120000 | P34: Hoàn thành
A35: DH2025-0034 | B35: 45737 | C35: KH029 | D35: Đại lý Hải Âu | E35: Doanh nghiệp | F35: Miền Bắc | G35: Bắc Ninh | H35: Điện tử | I35: Loa thông minh | J35: Website | K35: Trần Quốc Bảo | L35: 10 | M35: 1995000 | N35: 0.15 | O35: 1200000 | P35: Hoàn thành
A36: DH2025-0035 | B36: 45737 | C36: KH004 | D36: Vũ Thị Giang | E36: Cá nhân | F36: Miền Bắc | G36: Bắc Ninh | H36: Mỹ phẩm | I36: Kem chống nắng | J36: Cửa hàng | K36: Phạm Đức Huy | L36: 1 | M36: 320000 | N36: 0 | O36: 150000 | P36: Hoàn thành
A37: DH2025-0036 | B37: 45741 | C37: KH002 | D37: Phan Minh Bình | E37: Cá nhân | F37: Miền Bắc | G37: Hà Nội | H37: Điện tử | I37: Sạc dự phòng 20000mAh | J37: Sàn TMĐT | K37: Nguyễn Minh Anh | L37: 2 | M37: 690000 | N37: 0 | O37: 410000 | P37: Hoàn thành
A38: DH2025-0037 | B38: 45744 | C38: KH036 | D38: Hoàng Thị Phúc | E38: Cá nhân | F38: Miền Bắc | G38: Bắc Ninh | H38: Điện tử | I38: Sạc dự phòng 20000mAh | J38: Sàn TMĐT | K38: Nguyễn Minh Anh | L38: 1 | M38: 724000 | N38: 0 | O38: 410000 | P38: Hoàn thành
A39: DH2025-0038 | B39: 45745 | C39: KH024 | D39: Phạm Thu Hiếu | E39: Cá nhân | F39: Miền Bắc | G39: Quảng Ninh | H39: Thực phẩm | I39: Trà thảo mộc hộp | J39: Sàn TMĐT | L39: 1 | M39: 210000 | N39: 0.05 | O39: 120000 | P39: Hoàn thành
A40: DH2025-0039 | B40: 45746 | C40: KH030 | D40: Đặng Hoàng Hiếu | E40: Cá nhân | F40: Miền Nam | G40: Cần Thơ | H40: Thời trang | I40: Áo khoác gió | J40: Cửa hàng | K40: Võ Ngọc Lan | L40: 1 | M40: 750000 | N40: 0.15 | O40: 390000 | P40: Hoàn thành
...

Sheet Làm sạch dữ liệu
A4: 1. Nhật ký các vấn đề chất lượng dữ liệu và cách xử lý
A5: STT | B5: Vấn đề phát hiện | C5: Cột | D5: Số dòng ảnh hưởng | E5: Cách xử lý | F5: Mức độ
A6: 1 | B6: Dòng trùng lặp (trùng Mã đơn hàng) | C6: Mã đơn hàng | D6: =ROUND(COUNTA('Dữ liệu thô'!$A$2:$A$207)-SUMPRODUCT(1/COUNTIF('Dữ liệu thô'!$A$2:$A$207,'Dữ liệu thô'!$A$2:$A$207)),0) -> 6 | E6: Xóa dòng trùng, giữ 1 dòng duy nhất cho mỗi Mã đơn hàng | F6: Cao
A7: 2 | B7: Ngày đặt hàng lưu dạng văn bản (dd/mm/yyyy) | C7: Ngày đặt hàng | D7: =SUMPRODUCT(--ISTEXT('Dữ liệu thô'!$B$2:$B$207)) -> 7 | E7: Chuyển văn bản sang kiểu ngày (DATE) để tính theo tháng/quý/thứ | F7: Cao
A8: 3 | B8: Tên khu vực viết hoa/thường lẫn lộn, thừa khoảng trắng | C8: Khu vực | D8: =SUMPRODUCT(--((EXACT('Dữ liệu thô'!$F$2:$F$207,"Miền Bắc")+EXACT('Dữ liệu thô'!$F$2:$F$207,"Miền Trung")+EXACT('Dữ liệu thô'!$F$2:$F$207,"Miền Nam"))=0)) -> 9 | E8: Chuẩn hóa về 3 giá trị: Miền Bắc / Miền Trung / Miền Nam | F8: Trung bình
A9: 4 | B9: Trạng thái đơn hàng sai chuẩn chính tả/viết hoa | C9: Trạng thái | D9: =SUMPRODUCT(--((EXACT('Dữ liệu thô'!$P$2:$P$207,"Hoàn thành")+EXACT('Dữ liệu thô'!$P$2:$P$207,"Đã hủy")+EXACT('Dữ liệu thô'!$P$2:$P$207,"Hoàn trả"))=0)) -> 5 | E9: Chuẩn hóa về: Hoàn thành / Đã hủy / Hoàn trả | F9: Cao
A10: 5 | B10: Tên sản phẩm thừa khoảng trắng | C10: Sản phẩm | D10: =SUMPRODUCT(--(LEN('Dữ liệu thô'!$I$2:$I$207)<>LEN(TRIM('Dữ liệu thô'!$I$2:$I$207)))) -> 5 | E10: Dùng TRIM để xóa khoảng trắng thừa, tránh tách thành 2 sản phẩm khi thống kê | F10: Trung bình
A11: 6 | B11: Thiếu giá trị Kênh bán | C11: Kênh bán | D11: =COUNTBLANK('Dữ liệu thô'!$J$2:$J$207) -> 4 | E11: Điền giá trị xuất hiện nhiều nhất (Mode) = 'Website' | F11: Trung bình
A12: 7 | B12: Thiếu giá trị Nhân viên bán hàng | C12: Nhân viên | D12: =COUNTBLANK('Dữ liệu thô'!$K$2:$K$207) -> 4 | E12: Điền nhãn 'Chưa xác định' để không mất đơn hàng khỏi báo cáo | F12: Trung bình
A13: 8 | B13: Giảm giá nhập sai thang đo (10 thay vì 10%) | C13: Giảm giá | D13: =COUNTIF('Dữ liệu thô'!$N$2:$N$207,">1") -> 6 | E13: Chia 100 các giá trị > 1 để đưa về dạng phần trăm | F13: Cao
A15: 2. Tổng hợp trước và sau làm sạch
B16: Chỉ tiêu | D16: Giá trị | E16: Ghi chú
B17: Số dòng dữ liệu thô | D17: =COUNTA('Dữ liệu thô'!$A$2:$A$207) -> 206 | E17: Sheet 'Dữ liệu thô'
B18: Số dòng sau làm sạch | D18: =COUNTA('Dữ liệu sạch'!$A$2:$A$201) -> 200 | E18: Sheet 'Dữ liệu sạch'
B19: Số dòng đã loại bỏ | D19: =D17-D18 -> 6 | E19: Chính là số dòng trùng lặp
B20: Tỷ lệ dữ liệu giữ lại | D20: =D18/D17 -> 0.97087379 | E20: Số dòng sạch / số dòng thô
A22: 3. Kiểm tra chất lượng sau làm sạch (sheet 'Dữ liệu sạch')
A23: STT | B23: Tiêu chí kiểm tra | D23: Kết quả | E23: Kỳ vọng | F23: Trạng thái
A24: 1 | B24: Số Mã đơn hàng bị trùng | D24: =ROUND(COUNTA('Dữ liệu sạch'!$A$2:$A$201)-SUMPRODUCT(1/COUNTIF('Dữ liệu sạch'!$A$2:$A$201,'Dữ liệu sạch'!$A$2:$A$201)),0) -> 0 | E24: 0 | F24: =IF(D24=E24,"Đạt","Lỗi") -> Đạt
A25: 2 | B25: Số ô trống trong các cột bắt buộc (A:R) | D25: =COUNTBLANK('Dữ liệu sạch'!$A$2:$R$201) -> 0 | E25: 0 | F25: =IF(D25=E25,"Đạt","Lỗi") -> Đạt
A26: 3 | B26: Số ngày đang ở dạng văn bản | D26: =SUMPRODUCT(--ISTEXT('Dữ liệu sạch'!$B$2:$B$201)) -> 0 | E26: 0 | F26: =IF(D26=E26,"Đạt","Lỗi") -> Đạt
A27: 4 | B27: Số dòng có Giảm giá > 100% | D27: =COUNTIF('Dữ liệu sạch'!$P$2:$P$201,">1") -> 0 | E27: 0 | F27: =IF(D27=E27,"Đạt","Lỗi") -> Đạt
A28: 5 | B28: Số dòng có Số lượng ≤ 0 | D28: =COUNTIF('Dữ liệu sạch'!$N$2:$N$201,"<=0") -> 0 | E28: 0 | F28: =IF(D28=E28,"Đạt","Lỗi") -> Đạt
A30: 4. Kiểm tra chéo: tổng doanh thu thực ở các bảng phân tích phải khớp với Dữ liệu sạch
A31: STT | B31: Bảng phân tích | D31: Tổng doanh thu | E31: Chênh lệch so với dữ liệu gốc | F31: Trạng thái
A32: 1 | B32: Doanh thu theo tháng | D32: ='PT Thời gian'!D18 -> 346260650 | E32: =D32-SUM('Dữ liệu sạch'!$W$2:$W$201) -> 0 | F32: =IF(ABS(E32)<1,"Khớp","Lệch") -> Khớp
A33: 2 | B33: Doanh thu theo quý | D33: ='PT Thời gian'!C27 -> 346260650 | E33: =D33-SUM('Dữ liệu sạch'!$W$2:$W$201) -> 0 | F33: =IF(ABS(E33)<1,"Khớp","Lệch") -> Khớp
A34: 3 | B34: Doanh thu theo danh mục | D34: ='PT Sản phẩm'!D11 -> 346260650 | E34: =D34-SUM('Dữ liệu sạch'!$W$2:$W$201) -> 0 | F34: =IF(ABS(E34)<1,"Khớp","Lệch") -> Khớp
A35: 4 | B35: Doanh thu theo sản phẩm | D35: ='PT Sản phẩm'!D34 -> 346260650 | E35: =D35-SUM('Dữ liệu sạch'!$W$2:$W$201) -> 0 | F35: =IF(ABS(E35)<1,"Khớp","Lệch") -> Khớp
A36: 5 | B36: Doanh thu theo khu vực | D36: ='PT Khu vực - Kênh'!C9 -> 346260650 | E36: =D36-SUM('Dữ liệu sạch'!$W$2:$W$201) -> 0 | F36: =IF(ABS(E36)<1,"Khớp","Lệch") -> Khớp
A37: 6 | B37: Doanh thu theo tỉnh/thành | D37: ='PT Khu vực - Kênh'!D26 -> 346260650 | E37: =D37-SUM('Dữ liệu sạch'!$W$2:$W$201) -> 0 | F37: =IF(ABS(E37)<1,"Khớp","Lệch") -> Khớp
A38: 7 | B38: Doanh thu theo kênh bán | D38: ='PT Khu vực - Kênh'!C35 -> 346260650 | E38: =D38-SUM('Dữ liệu sạch'!$W$2:$W$201) -> 0 | F38: =IF(ABS(E38)<1,"Khớp","Lệch") -> Khớp
A39: 8 | B39: Doanh thu theo nhân viên | D39: ='PT Khách hàng - NV'!C21 -> 346260650 | E39: =D39-SUM('Dữ liệu sạch'!$W$2:$W$201) -> 0 | F39: =IF(ABS(E39)<1,"Khớp","Lệch") -> Khớp
A40: 9 | B40: Doanh thu theo phân khúc KH | D40: ='PT Khách hàng - NV'!D8 -> 346260650 | E40: =D40-SUM('Dữ liệu sạch'!$W$2:$W$201) -> 0 | F40: =IF(ABS(E40)<1,"Khớp","Lệch") -> Khớp
A41: 10 | B41: Doanh thu theo khách hàng | D41: =SUM('PT Khách hàng - NV'!F54:F113) -> 346260650 | E41: =D41-SUM('Dữ liệu sạch'!$W$2:$W$201) -> 0 | F41: =IF(ABS(E41)<1,"Khớp","Lệch") -> Khớp
B42: Doanh thu thực toàn bộ dữ liệu sạch | D42: =SUM('Dữ liệu sạch'!$W$2:$W$201) -> 346260650

Sheet Dữ liệu sạch
A1: Mã đơn hàng | B1: Ngày đặt hàng | C1: Tháng | D1: Quý | E1: Mã KH | F1: Tên khách hàng | G1: Phân khúc | H1: Khu vực | I1: Tỉnh/Thành | J1: Danh mục | K1: Sản phẩm | L1: Kênh bán | M1: Nhân viên bán hàng | N1: Số lượng | O1: Đơn giá (VNĐ) | P1: Giảm giá % | Q1: Giá vốn đơn vị (VNĐ) | R1: Trạng thái | S1: Doanh thu (VNĐ) | T1: Tổng giá vốn (VNĐ) | U1: Lợi nhuận (VNĐ) | V1: Biên LN % | W1: Doanh thu thực (đơn hoàn thành) | X1: Lợi nhuận thực (đơn hoàn thành) | Y1: Thứ trong tuần (1=T2..7=CN) | AA1: Ghi chú
A2: DH2025-0001 | B2: 45662 | C2: =MONTH(B2) -> 1 | D2: ="Q"&ROUNDUP(C2/3,0) -> Q1 | E2: KH040 | F2: Bùi Minh An | G2: Cá nhân | H2: Miền Bắc | I2: Quảng Ninh | J2: Mỹ phẩm | K2: Serum Vitamin C | L2: Website | M2: Trần Quốc Bảo | N2: 2 | O2: 588000 | P2: 0.15 | Q2: 260000 | R2: Hoàn thành | S2: =N2*O2*(1-P2) -> 999600 | T2: =N2*Q2 -> 520000 | U2: =S2-T2 -> 479600 | V2: =IF(S2=0,0,U2/S2) -> 0.47979192 | W2: =IF(R2="Hoàn thành",S2,"") -> 999600 | X2: =IF(R2="Hoàn thành",U2,"") -> 479600 | Y2: =WEEKDAY(B2,2) -> 7 | AA2: Chữ xanh: dữ liệu đầu vào (đã làm sạch). Chữ đen: công thức.
A3: DH2025-0002 | B3: 45666 | C3: =MONTH(B3) -> 1 | D3: ="Q"&ROUNDUP(C3/3,0) -> Q1 | E3: KH040 | F3: Bùi Minh An | G3: Cá nhân | H3: Miền Bắc | I3: Quảng Ninh | J3: Mỹ phẩm | K3: Son lì | L3: Website | M3: Phạm Đức Huy | N3: 3 | O3: 290000 | P3: 0.1 | Q3: 120000 | R3: Hoàn thành | S3: =N3*O3*(1-P3) -> 783000 | T3: =N3*Q3 -> 360000 | U3: =S3-T3 -> 423000 | V3: =IF(S3=0,0,U3/S3) -> 0.54022989 | W3: =IF(R3="Hoàn thành",S3,"") -> 783000 | X3: =IF(R3="Hoàn thành",U3,"") -> 423000 | Y3: =WEEKDAY(B3,2) -> 4 | AA3: Doanh thu = Số lượng × Đơn giá × (1 − Giảm giá).
A4: DH2025-0003 | B4: 45667 | C4: =MONTH(B4) -> 1 | D4: ="Q"&ROUNDUP(C4/3,0) -> Q1 | E4: KH046 | F4: Phan Minh Khoa | G4: Cá nhân | H4: Miền Bắc | I4: Quảng Ninh | J4: Điện tử | K4: Tai nghe Bluetooth | L4: Sàn TMĐT | M4: Lê Thu Hà | N4: 1 | O4: 892000 | P4: 0.2 | Q4: 520000 | R4: Hoàn trả | S4: =N4*O4*(1-P4) -> 713600 | T4: =N4*Q4 -> 520000 | U4: =S4-T4 -> 193600 | V4: =IF(S4=0,0,U4/S4) -> 0.27130045 | W4: =IF(R4="Hoàn thành",S4,"") | X4: =IF(R4="Hoàn thành",U4,"") | Y4: =WEEKDAY(B4,2) -> 5 | AA4: Lợi nhuận = Doanh thu − Số lượng × Giá vốn đơn vị.
A5: DH2025-0004 | B5: 45669 | C5: =MONTH(B5) -> 1 | D5: ="Q"&ROUNDUP(C5/3,0) -> Q1 | E5: KH043 | F5: Phạm Hoàng Giang | G5: Cá nhân | H5: Miền Trung | I5: Huế | J5: Gia dụng | K5: Ấm siêu tốc | L5: Sàn TMĐT | M5: Trần Quốc Bảo | N5: 1 | O5: 520000 | P5: 0 | Q5: 310000 | R5: Hoàn thành | S5: =N5*O5*(1-P5) -> 520000 | T5: =N5*Q5 -> 310000 | U5: =S5-T5 -> 210000 | V5: =IF(S5=0,0,U5/S5) -> 0.40384615 | W5: =IF(R5="Hoàn thành",S5,"") -> 520000 | X5: =IF(R5="Hoàn thành",U5,"") -> 210000 | Y5: =WEEKDAY(B5,2) -> 7 | AA5: Cột W, X chỉ tính đơn 'Hoàn thành'; đơn hủy/hoàn trả để trống để không ảnh hưởng thống kê.
A6: DH2025-0005 | B6: 45670 | C6: =MONTH(B6) -> 1 | D6: ="Q"&ROUNDUP(C6/3,0) -> Q1 | E6: KH008 | F6: Hoàng Đức Trang | G6: Cá nhân | H6: Miền Nam | I6: Bình Dương | J6: Thực phẩm | K6: Trà thảo mộc hộp | L6: Cửa hàng | M6: Trần Quốc Bảo | N6: 1 | O6: 200000 | P6: 0 | Q6: 120000 | R6: Hoàn thành | S6: =N6*O6*(1-P6) -> 200000 | T6: =N6*Q6 -> 120000 | U6: =S6-T6 -> 80000 | V6: =IF(S6=0,0,U6/S6) -> 0.4 | W6: =IF(R6="Hoàn thành",S6,"") -> 200000 | X6: =IF(R6="Hoàn thành",U6,"") -> 80000 | Y6: =WEEKDAY(B6,2) -> 1
A7: DH2025-0006 | B7: 45674 | C7: =MONTH(B7) -> 1 | D7: ="Q"&ROUNDUP(C7/3,0) -> Q1 | E7: KH008 | F7: Hoàng Đức Trang | G7: Cá nhân | H7: Miền Nam | I7: Bình Dương | J7: Điện tử | K7: Loa thông minh | L7: Website | M7: Nguyễn Minh Anh | N7: 1 | O7: 1900000 | P7: 0 | Q7: 1200000 | R7: Hoàn thành | S7: =N7*O7*(1-P7) -> 1900000 | T7: =N7*Q7 -> 1200000 | U7: =S7-T7 -> 700000 | V7: =IF(S7=0,0,U7/S7) -> 0.36842105 | W7: =IF(R7="Hoàn thành",S7,"") -> 1900000 | X7: =IF(R7="Hoàn thành",U7,"") -> 700000 | Y7: =WEEKDAY(B7,2) -> 5
A8: DH2025-0007 | B8: 45676 | C8: =MONTH(B8) -> 1 | D8: ="Q"&ROUNDUP(C8/3,0) -> Q1 | E8: KH051 | F8: Đỗ Minh Long | G8: Cá nhân | H8: Miền Bắc | I8: Bắc Ninh | J8: Thực phẩm | K8: Hạt dinh dưỡng mix | L8: Website | M8: Bùi Thanh Tùng | N8: 1 | O8: 340000 | P8: 0 | Q8: 220000 | R8: Hoàn thành | S8: =N8*O8*(1-P8) -> 340000 | T8: =N8*Q8 -> 220000 | U8: =S8-T8 -> 120000 | V8: =IF(S8=0,0,U8/S8) -> 0.35294118 | W8: =IF(R8="Hoàn thành",S8,"") -> 340000 | X8: =IF(R8="Hoàn thành",U8,"") -> 120000 | Y8: =WEEKDAY(B8,2) -> 7
A9: DH2025-0008 | B9: 45676 | C9: =MONTH(B9) -> 1 | D9: ="Q"&ROUNDUP(C9/3,0) -> Q1 | E9: KH048 | F9: Phạm Thị Quân | G9: Cá nhân | H9: Miền Bắc | I9: Hải Phòng | J9: Thực phẩm | K9: Cà phê rang xay 1kg | L9: Cửa hàng | M9: Võ Ngọc Lan | N9: 1 | O9: 380000 | P9: 0.05 | Q9: 250000 | R9: Hoàn thành | S9: =N9*O9*(1-P9) -> 361000 | T9: =N9*Q9 -> 250000 | U9: =S9-T9 -> 111000 | V9: =IF(S9=0,0,U9/S9) -> 0.30747922 | W9: =IF(R9="Hoàn thành",S9,"") -> 361000 | X9: =IF(R9="Hoàn thành",U9,"") -> 111000 | Y9: =WEEKDAY(B9,2) -> 7
A10: DH2025-0009 | B10: 45678 | C10: =MONTH(B10) -> 1 | D10: ="Q"&ROUNDUP(C10/3,0) -> Q1 | E10: KH054 | F10: Phan Hoàng Bình | G10: Cá nhân | H10: Miền Trung | I10: Khánh Hòa | J10: Thời trang | K10: Giày thể thao | L10: Website | M10: Lê Thu Hà | N10: 1 | O10: 1500000 | P10: 0.2 | Q10: 800000 | R10: Hoàn thành | S10: =N10*O10*(1-P10) -> 1200000 | T10: =N10*Q10 -> 800000 | U10: =S10-T10 -> 400000 | V10: =IF(S10=0,0,U10/S10) -> 0.33333333 | W10: =IF(R10="Hoàn thành",S10,"") -> 1200000 | X10: =IF(R10="Hoàn thành",U10,"") -> 400000 | Y10: =WEEKDAY(B10,2) -> 2
A11: DH2025-0010 | B11: 45678 | C11: =MONTH(B11) -> 1 | D11: ="Q"&ROUNDUP(C11/3,0) -> Q1 | E11: KH011 | F11: Công ty CP Bình Minh | G11: Doanh nghiệp | H11: Miền Bắc | I11: Quảng Ninh | J11: Thời trang | K11: Áo khoác gió | L11: Đại lý | M11: Võ Ngọc Lan | N11: 8 | O11: 750000 | P11: 0.05 | Q11: 390000 | R11: Đã hủy | S11: =N11*O11*(1-P11) -> 5700000 | T11: =N11*Q11 -> 3120000 | U11: =S11-T11 -> 2580000 | V11: =IF(S11=0,0,U11/S11) -> 0.45263158 | W11: =IF(R11="Hoàn thành",S11,"") | X11: =IF(R11="Hoàn thành",U11,"") | Y11: =WEEKDAY(B11,2) -> 2
A12: DH2025-0011 | B12: 45679 | C12: =MONTH(B12) -> 1 | D12: ="Q"&ROUNDUP(C12/3,0) -> Q1 | E12: KH031 | F12: Vũ Đức Hà | G12: Cá nhân | H12: Miền Nam | I12: Cần Thơ | J12: Thời trang | K12: Túi xách nữ | L12: Website | M12: Nguyễn Minh Anh | N12: 1 | O12: 1140000 | P12: 0.1 | Q12: 620000 | R12: Hoàn thành | S12: =N12*O12*(1-P12) -> 1026000 | T12: =N12*Q12 -> 620000 | U12: =S12-T12 -> 406000 | V12: =IF(S12=0,0,U12/S12) -> 0.3957115 | W12: =IF(R12="Hoàn thành",S12,"") -> 1026000 | X12: =IF(R12="Hoàn thành",U12,"") -> 406000 | Y12: =WEEKDAY(B12,2) -> 3
A13: DH2025-0012 | B13: 45681 | C13: =MONTH(B13) -> 1 | D13: ="Q"&ROUNDUP(C13/3,0) -> Q1 | E13: KH056 | F13: Lê Anh Mai | G13: Cá nhân | H13: Miền Nam | I13: Đồng Nai | J13: Mỹ phẩm | K13: Serum Vitamin C | L13: Website | M13: Đặng Hoàng Nam | N13: 2 | O13: 588000 | P13: 0.1 | Q13: 260000 | R13: Hoàn thành | S13: =N13*O13*(1-P13) -> 1058400 | T13: =N13*Q13 -> 520000 | U13: =S13-T13 -> 538400 | V13: =IF(S13=0,0,U13/S13) -> 0.50869237 | W13: =IF(R13="Hoàn thành",S13,"") -> 1058400 | X13: =IF(R13="Hoàn thành",U13,"") -> 538400 | Y13: =WEEKDAY(B13,2) -> 5
A14: DH2025-0013 | B14: 45681 | C14: =MONTH(B14) -> 1 | D14: ="Q"&ROUNDUP(C14/3,0) -> Q1 | E14: KH040 | F14: Bùi Minh An | G14: Cá nhân | H14: Miền Bắc | I14: Quảng Ninh | J14: Gia dụng | K14: Ấm siêu tốc | L14: Website | M14: Võ Ngọc Lan | N14: 1 | O14: 520000 | P14: 0 | Q14: 310000 | R14: Đã hủy | S14: =N14*O14*(1-P14) -> 520000 | T14: =N14*Q14 -> 310000 | U14: =S14-T14 -> 210000 | V14: =IF(S14=0,0,U14/S14) -> 0.40384615 | W14: =IF(R14="Hoàn thành",S14,"") | X14: =IF(R14="Hoàn thành",U14,"") | Y14: =WEEKDAY(B14,2) -> 5
A15: DH2025-0014 | B15: 45684 | C15: =MONTH(B15) -> 1 | D15: ="Q"&ROUNDUP(C15/3,0) -> Q1 | E15: KH055 | F15: Công ty CP Sao Việt | G15: Doanh nghiệp | H15: Miền Nam | I15: Bình Dương | J15: Điện tử | K15: Tai nghe Bluetooth | L15: Đại lý | M15: Nguyễn Minh Anh | N15: 3 | O15: 808000 | P15: 0.1 | Q15: 520000 | R15: Hoàn thành | S15: =N15*O15*(1-P15) -> 2181600 | T15: =N15*Q15 -> 1560000 | U15: =S15-T15 -> 621600 | V15: =IF(S15=0,0,U15/S15) -> 0.28492849 | W15: =IF(R15="Hoàn thành",S15,"") -> 2181600 | X15: =IF(R15="Hoàn thành",U15,"") -> 621600 | Y15: =WEEKDAY(B15,2) -> 1
A16: DH2025-0015 | B16: 45685 | C16: =MONTH(B16) -> 1 | D16: ="Q"&ROUNDUP(C16/3,0) -> Q1 | E16: KH057 | F16: Huỳnh Thu Hải | G16: Cá nhân | H16: Miền Nam | I16: Bình Dương | J16: Thời trang | K16: Áo khoác gió | L16: Sàn TMĐT | M16: Võ Ngọc Lan | N16: 1 | O16: 750000 | P16: 0 | Q16: 390000 | R16: Hoàn thành | S16: =N16*O16*(1-P16) -> 750000 | T16: =N16*Q16 -> 390000 | U16: =S16-T16 -> 360000 | V16: =IF(S16=0,0,U16/S16) -> 0.48 | W16: =IF(R16="Hoàn thành",S16,"") -> 750000 | X16: =IF(R16="Hoàn thành",U16,"") -> 360000 | Y16: =WEEKDAY(B16,2) -> 2
A17: DH2025-0016 | B17: 45685 | C17: =MONTH(B17) -> 1 | D17: ="Q"&ROUNDUP(C17/3,0) -> Q1 | E17: KH043 | F17: Phạm Hoàng Giang | G17: Cá nhân | H17: Miền Trung | I17: Huế | J17: Thực phẩm | K17: Hạt dinh dưỡng mix | L17: Cửa hàng | M17: Võ Ngọc Lan | N17: 4 | O17: 340000 | P17: 0.15 | Q17: 220000 | R17: Hoàn thành | S17: =N17*O17*(1-P17) -> 1156000 | T17: =N17*Q17 -> 880000 | U17: =S17-T17 -> 276000 | V17: =IF(S17=0,0,U17/S17) -> 0.23875433 | W17: =IF(R17="Hoàn thành",S17,"") -> 1156000 | X17: =IF(R17="Hoàn thành",U17,"") -> 276000 | Y17: =WEEKDAY(B17,2) -> 2
... A201: DH2025-0200 | B201: 46020 | C201: =MONTH(B201) -> 12 | D201: ="Q"&ROUNDUP(C201/3,0) -> Q4 | E201: KH018 | F201: Công ty CP Trường Sơn | G201: Doanh nghiệp | H201: Miền Bắc | I201: Hải Phòng | J201: Điện tử | K201: Bàn phím cơ | L201: Website | M201: Phạm Đức Huy | N201: 5 | O201: 1260000 | P201: 0.1 | Q201: 720000 | R201: Hoàn thành | S201: =N201*O201*(1-P201) -> 5670000 | T201: =N201*Q201 -> 3600000 | U201: =S201-T201 -> 2070000 | V201: =IF(S201=0,0,U201/S201) -> 0.36507937 | W201: =IF(R201="Hoàn thành",S201,"") -> 5670000 | X201: =IF(R201="Hoàn thành",U201,"") -> 2070000 | Y201: =WEEKDAY(B201,2) -> 1

Sheet Thống kê mô tả
A4: 1. Thống kê mô tả giá trị đơn hàng
A5: Chỉ tiêu | B5: Doanh thu / đơn (VNĐ) | C5: Lợi nhuận / đơn (VNĐ) | D5: Diễn giải
A6: Số quan sát (đơn hoàn thành) | B6: =COUNT('Dữ liệu sạch'!$W$2:$W$201) -> 176 | C6: =COUNT('Dữ liệu sạch'!$X$2:$X$201) -> 176
A7: Tổng | B7: =SUM('Dữ liệu sạch'!$W$2:$W$201) -> 346260650 | C7: =SUM('Dữ liệu sạch'!$X$2:$X$201) -> 131000650
A8: Trung bình | B8: =AVERAGE('Dữ liệu sạch'!$W$2:$W$201) -> 1967390.1 | C8: =AVERAGE('Dữ liệu sạch'!$X$2:$X$201) -> 744321.88
A9: Trung vị | B9: =MEDIAN('Dữ liệu sạch'!$W$2:$W$201) -> 1151750 | C9: =MEDIAN('Dữ liệu sạch'!$X$2:$X$201) -> 487250 | D9: =IF(B9<B8,"Trung vị < Trung bình: phân phối lệch phải, một số đơn giá trị rất lớn kéo trung bình lên","Trung vị ≥ Trung bình: phân phối tương đối cân đối") -> Trung vị < Trung bình: phân phối lệch phải, một số đơn giá trị rất lớn kéo trung bình lên
A10: Nhỏ nhất | B10: =MIN('Dữ liệu sạch'!$W$2:$W$201) -> 178500 | C10: =MIN('Dữ liệu sạch'!$X$2:$X$201) -> 52000
A11: Tứ phân vị Q1 (25%) | B11: =QUARTILE('Dữ liệu sạch'!$W$2:$W$201,1) -> 560000 | C11: =QUARTILE('Dữ liệu sạch'!$X$2:$X$201,1) -> 244000
A12: Tứ phân vị Q3 (75%) | B12: =QUARTILE('Dữ liệu sạch'!$W$2:$W$201,3) -> 2198700 | C12: =QUARTILE('Dữ liệu sạch'!$X$2:$X$201,3) -> 828500
A13: Lớn nhất | B13: =MAX('Dữ liệu sạch'!$W$2:$W$201) -> 16957500 | C13: =MAX('Dữ liệu sạch'!$X$2:$X$201) -> 5800000
A14: Độ lệch chuẩn | B14: =STDEV('Dữ liệu sạch'!$W$2:$W$201) -> 2408521.1 | C14: =STDEV('Dữ liệu sạch'!$X$2:$X$201) -> 872038.48
A15: Hệ số biến thiên (CV) | B15: =B14/B8 -> 1.2242214 | C15: =C14/C8 -> 1.1715879 | D15: =IF(B15>1,"CV > 100%: giá trị đơn hàng biến động rất mạnh","CV ≤ 100%: mức biến động vừa phải") -> CV > 100%: giá trị đơn hàng biến động rất mạnh
A16: Độ lệch (Skewness) | B16: =SKEW('Dữ liệu sạch'!$W$2:$W$201) -> 2.9618068 | C16: =SKEW('Dữ liệu sạch'!$X$2:$X$201) -> 2.8453039
A17: Khoảng tứ phân vị (IQR) | B17: =B12-B11 -> 1638700 | C17: =C12-C11 -> 584500
A18: Ngưỡng ngoại lai trên (Q3 + 1,5 × IQR) | B18: =B12+1.5*B17 -> 4656750 | C18: =C12+1.5*C17 -> 1705250
A19: Số đơn ngoại lai | B19: =COUNTIF('Dữ liệu sạch'!$W$2:$W$201,">"&B18) -> 18 | C19: =COUNTIF('Dữ liệu sạch'!$X$2:$X$201,">"&C18) -> 19 | D19: ="Có "&B19&" đơn doanh thu vượt "&TEXT(B18,"#,##0")&" đ: nên phân tích riêng nhóm đơn lớn (thường là khách doanh nghiệp)" -> Có 18 đơn doanh thu vượt 4656750,0 đ: nên phân tích riêng nhóm đơn lớn (thường là khách doanh nghiệp)
A22: 2. Phân phối giá trị đơn hàng (histogram)
A23: Khoảng doanh thu / đơn | B23: Từ (≥, VNĐ) | C23: Đến (<, VNĐ) | D23: Số đơn | E23: Tỷ lệ
A24: Dưới 500 nghìn | B24: 0 | C24: 500000 | D24: =COUNTIFS('Dữ liệu sạch'!$W$2:$W$201,">="&B24,'Dữ liệu sạch'!$W$2:$W$201,"<"&C24) -> 35 | E24: =D24/$D$30 -> 0.19886364
A25: 500 nghìn – 1 triệu | B25: 500000 | C25: 1000000 | D25: =COUNTIFS('Dữ liệu sạch'!$W$2:$W$201,">="&B25,'Dữ liệu sạch'!$W$2:$W$201,"<"&C25) -> 44 | E25: =D25/$D$30 -> 0.25
A26: 1 – 2 triệu | B26: 1000000 | C26: 2000000 | D26: =COUNTIFS('Dữ liệu sạch'!$W$2:$W$201,">="&B26,'Dữ liệu sạch'!$W$2:$W$201,"<"&C26) -> 43 | E26: =D26/$D$30 -> 0.24431818
A27: 2 – 5 triệu | B27: 2000000 | C27: 5000000 | D27: =COUNTIFS('Dữ liệu sạch'!$W$2:$W$201,">="&B27,'Dữ liệu sạch'!$W$2:$W$201,"<"&C27) -> 37 | E27: =D27/$D$30 -> 0.21022727
A28: 5 – 10 triệu | B28: 5000000 | C28: 10000000 | D28: =COUNTIFS('Dữ liệu sạch'!$W$2:$W$201,">="&B28,'Dữ liệu sạch'!$W$2:$W$201,"<"&C28) -> 13 | E28: =D28/$D$30 -> 0.073863636
A29: Từ 10 triệu trở lên | B29: 10000000 | C29: 1000000000000 | D29: =COUNTIFS('Dữ liệu sạch'!$W$2:$W$201,">="&B29,'Dữ liệu sạch'!$W$2:$W$201,"<"&C29) -> 4 | E29: =D29/$D$30 -> 0.022727273
A30: Tổng | D30: =SUM(D24:D29) -> 176 | E30: =SUM(E24:E29) -> 1
A33: 3. Cơ cấu trạng thái đơn hàng
A34: Trạng thái | B34: Số đơn | C34: Tỷ lệ | D34: Nhận xét
A35: Hoàn thành | B35: =COUNTIF('Dữ liệu sạch'!$R$2:$R$201,A35) -> 176 | C35: =B35/$B$38 -> 0.88 | D35: Đơn tạo ra doanh thu và lợi nhuận
A36: Đã hủy | B36: =COUNTIF('Dữ liệu sạch'!$R$2:$R$201,A36) -> 12 | C36: =B36/$B$38 -> 0.06 | D36: Đơn khách hủy trước khi giao
A37: Hoàn trả | B37: =COUNTIF('Dữ liệu sạch'!$R$2:$R$201,A37) -> 12 | C37: =B37/$B$38 -> 0.06 | D37: Đơn đã giao nhưng khách trả lại
A38: Tổng | B38: =SUM(B35:B37) -> 200 | C38: =SUM(C35:C37) -> 1
A40: 4. Tương quan giữa các biến (tính trên toàn bộ 200 đơn)
A41: Cặp biến | B41: Hệ số tương quan r | C41: Mức độ | D41: Diễn giải
A42: Giảm giá ↔ Số lượng | B42: =CORREL('Dữ liệu sạch'!$P$2:$P$201,'Dữ liệu sạch'!$N$2:$N$201) -> 0.088519254 | C42: =IF(ABS(B42)<0.2,"Rất yếu",IF(ABS(B42)<0.4,"Yếu",IF(ABS(B42)<0.6,"Trung bình","Mạnh")))&IF(B42<0," (nghịch)"," (thuận)") -> Rất yếu (thuận) | D42: Giảm giá có kéo số lượng mua tăng không?
A43: Giảm giá ↔ Biên lợi nhuận | B43: =CORREL('Dữ liệu sạch'!$P$2:$P$201,'Dữ liệu sạch'!$V$2:$V$201) -> -0.47751254 | C43: =IF(ABS(B43)<0.2,"Rất yếu",IF(ABS(B43)<0.4,"Yếu",IF(ABS(B43)<0.6,"Trung bình","Mạnh")))&IF(B43<0," (nghịch)"," (thuận)") -> Trung bình (nghịch) | D43: r âm: giảm giá càng sâu, biên lợi nhuận càng thấp
A44: Số lượng ↔ Doanh thu | B44: =CORREL('Dữ liệu sạch'!$N$2:$N$201,'Dữ liệu sạch'!$S$2:$S$201) -> 0.73621078 | C44: =IF(ABS(B44)<0.2,"Rất yếu",IF(ABS(B44)<0.4,"Yếu",IF(ABS(B44)<0.6,"Trung bình","Mạnh")))&IF(B44<0," (nghịch)"," (thuận)") -> Mạnh (thuận) | D44: Doanh thu phụ thuộc bao nhiêu vào số lượng mua

Sheet PT Thời gian
A4: 1. Doanh thu theo tháng
A5: Tháng | B5: Số tháng | C5: Số đơn hoàn thành | D5: Doanh thu (VNĐ) | E5: Lợi nhuận (VNĐ) | F5: Biên LN | G5: Giá trị đơn TB (VNĐ) | H5: Tăng trưởng so tháng trước | I5: Doanh thu TB động 3 tháng
A6: Tháng 1 | B6: 1 | C6: =COUNTIFS('Dữ liệu sạch'!$C$2:$C$201,$B6,'Dữ liệu sạch'!$R$2:$R$201,"Hoàn thành") -> 13 | D6: =SUMIFS('Dữ liệu sạch'!$W$2:$W$201,'Dữ liệu sạch'!$C$2:$C$201,$B6) -> 12475600 | E6: =SUMIFS('Dữ liệu sạch'!$X$2:$X$201,'Dữ liệu sạch'!$C$2:$C$201,$B6) -> 4725600 | F6: =IF(D6=0,0,E6/D6) -> 0.37878739 | G6: =IF(C6=0,0,D6/C6) -> 959661.54 | H6: – | I6: –
A7: Tháng 2 | B7: 2 | C7: =COUNTIFS('Dữ liệu sạch'!$C$2:$C$201,$B7,'Dữ liệu sạch'!$R$2:$R$201,"Hoàn thành") -> 5 | D7: =SUMIFS('Dữ liệu sạch'!$W$2:$W$201,'Dữ liệu sạch'!$C$2:$C$201,$B7) -> 9850700 | E7: =SUMIFS('Dữ liệu sạch'!$X$2:$X$201,'Dữ liệu sạch'!$C$2:$C$201,$B7) -> 3800700 | F7: =IF(D7=0,0,E7/D7) -> 0.38583045 | G7: =IF(C7=0,0,D7/C7) -> 1970140 | H7: =IF(D6=0,0,D7/D6-1) -> -0.21040271 | I7: –
A8: Tháng 3 | B8: 3 | C8: =COUNTIFS('Dữ liệu sạch'!$C$2:$C$201,$B8,'Dữ liệu sạch'!$R$2:$R$201,"Hoàn thành") -> 17 | D8: =SUMIFS('Dữ liệu sạch'!$W$2:$W$201,'Dữ liệu sạch'!$C$2:$C$201,$B8) -> 50366500 | E8: =SUMIFS('Dữ liệu sạch'!$X$2:$X$201,'Dữ liệu sạch'!$C$2:$C$201,$B8) -> 15906500 | F8: =IF(D8=0,0,E8/D8) -> 0.31581508 | G8: =IF(C8=0,0,D8/C8) -> 2962735.3 | H8: =IF(D7=0,0,D8/D7-1) -> 4.1129869 | I8: =AVERAGE(D6:D8) -> 24230933
A9: Tháng 4 | B9: 4 | C9: =COUNTIFS('Dữ liệu sạch'!$C$2:$C$201,$B9,'Dữ liệu sạch'!$R$2:$R$201,"Hoàn thành") -> 12 | D9: =SUMIFS('Dữ liệu sạch'!$W$2:$W$201,'Dữ liệu sạch'!$C$2:$C$201,$B9) -> 20054200 | E9: =SUMIFS('Dữ liệu sạch'!$X$2:$X$201,'Dữ liệu sạch'!$C$2:$C$201,$B9) -> 7844200 | F9: =IF(D9=0,0,E9/D9) -> 0.39114998 | G9: =IF(C9=0,0,D9/C9) -> 1671183.3 | H9: =IF(D8=0,0,D9/D8-1) -> -0.60183455 | I9: =AVERAGE(D7:D9) -> 26757133
A10: Tháng 5 | B10: 5 | C10: =COUNTIFS('Dữ liệu sạch'!$C$2:$C$201,$B10,'Dữ liệu sạch'!$R$2:$R$201,"Hoàn thành") -> 13 | D10: =SUMIFS('Dữ liệu sạch'!$W$2:$W$201,'Dữ liệu sạch'!$C$2:$C$201,$B10) -> 17846350 | E10: =SUMIFS('Dữ liệu sạch'!$X$2:$X$201,'Dữ liệu sạch'!$C$2:$C$201,$B10) -> 7896350 | F10: =IF(D10=0,0,E10/D10) -> 0.44246302 | G10: =IF(C10=0,0,D10/C10) -> 1372796.2 | H10: =IF(D9=0,0,D10/D9-1) -> -0.11009414 | I10: =AVERAGE(D8:D10) -> 29422350
A11: Tháng 6 | B11: 6 | C11: =COUNTIFS('Dữ liệu sạch'!$C$2:$C$201,$B11,'Dữ liệu sạch'!$R$2:$R$201,"Hoàn thành") -> 15 | D11: =SUMIFS('Dữ liệu sạch'!$W$2:$W$201,'Dữ liệu sạch'!$C$2:$C$201,$B11) -> 25664500 | E11: =SUMIFS('Dữ liệu sạch'!$X$2:$X$201,'Dữ liệu sạch'!$C$2:$C$201,$B11) -> 11494500 | F11: =IF(D11=0,0,E11/D11) -> 0.44787547 | G11: =IF(C11=0,0,D11/C11) -> 1710966.7 | H11: =IF(D10=0,0,D11/D10-1) -> 0.43808118 | I11: =AVERAGE(D9:D11) -> 21188350
A12: Tháng 7 | B12: 7 | C12: =COUNTIFS('Dữ liệu sạch'!$C$2:$C$201,$B12,'Dữ liệu sạch'!$R$2:$R$201,"Hoàn thành") -> 13 | D12: =SUMIFS('Dữ liệu sạch'!$W$2:$W$201,'Dữ liệu sạch'!$C$2:$C$201,$B12) -> 33776500 | E12: =SUMIFS('Dữ liệu sạch'!$X$2:$X$201,'Dữ liệu sạch'!$C$2:$C$201,$B12) -> 12676500 | F12: =IF(D12=0,0,E12/D12) -> 0.37530532 | G12: =IF(C12=0,0,D12/C12) -> 2598192.3 | H12: =IF(D11=0,0,D12/D11-1) -> 0.31607863 | I12: =AVERAGE(D10:D12) -> 25762450
A13: Tháng 8 | B13: 8 | C13: =COUNTIFS('Dữ liệu sạch'!$C$2:$C$201,$B13,'Dữ liệu sạch'!$R$2:$R$201,"Hoàn thành") -> 16 | D13: =SUMIFS('Dữ liệu sạch'!$W$2:$W$201,'Dữ liệu sạch'!$C$2:$C$201,$B13) -> 19911000 | E13: =SUMIFS('Dữ liệu sạch'!$X$2:$X$201,'Dữ liệu sạch'!$C$2:$C$201,$B13) -> 7441000 | F13: =IF(D13=0,0,E13/D13) -> 0.37371302 | G13: =IF(C13=0,0,D13/C13) -> 1244437.5 | H13: =IF(D12=0,0,D13/D12-1) -> -0.41050731 | I13: =AVERAGE(D11:D13) -> 26450667
A14: Tháng 9 | B14: 9 | C14: =COUNTIFS('Dữ liệu sạch'!$C$2:$C$201,$B14,'Dữ liệu sạch'!$R$2:$R$201,"Hoàn thành") -> 15 | D14: =SUMIFS('Dữ liệu sạch'!$W$2:$W$201,'Dữ liệu sạch'!$C$2:$C$201,$B14) -> 42028450 | E14: =SUMIFS('Dữ liệu sạch'!$X$2:$X$201,'Dữ liệu sạch'!$C$2:$C$201,$B14) -> 15618450 | F14: =IF(D14=0,0,E14/D14) -> 0.37161613 | G14: =IF(C14=0,0,D14/C14) -> 2801896.7 | H14: =IF(D13=0,0,D14/D13-1) -> 1.1108156 | I14: =AVERAGE(D12:D14) -> 31905317
A15: Tháng 10 | B15: 10 | C15: =COUNTIFS('Dữ liệu sạch'!$C$2:$C$201,$B15,'Dữ liệu sạch'!$R$2:$R$201,"Hoàn thành") -> 13 | D15: =SUMIFS('Dữ liệu sạch'!$W$2:$W$201,'Dữ liệu sạch'!$C$2:$C$201,$B15) -> 34703050 | E15: =SUMIFS('Dữ liệu sạch'!$X$2:$X$201,'Dữ liệu sạch'!$C$2:$C$201,$B15) -> 13223050 | F15: =IF(D15=0,0,E15/D15) -> 0.38103423 | G15: =IF(C15=0,0,D15/C15) -> 2669465.4 | H15: =IF(D14=0,0,D15/D14-1) -> -0.17429622 | I15: =AVERAGE(D13:D15) -> 32214167
A16: Tháng 11 | B16: 11 | C16: =COUNTIFS('Dữ liệu sạch'!$C$2:$C$201,$B16,'Dữ liệu sạch'!$R$2:$R$201,"Hoàn thành") -> 12 | D16: =SUMIFS('Dữ liệu sạch'!$W$2:$W$201,'Dữ liệu sạch'!$C$2:$C$201,$B16) -> 15014200 | E16: =SUMIFS('Dữ liệu sạch'!$X$2:$X$201,'Dữ liệu sạch'!$C$2:$C$201,$B16) -> 5874200 | F16: =IF(D16=0,0,E16/D16) -> 0.39124296 | G16: =IF(C16=0,0,D16/C16) -> 1251183.3 | H16: =IF(D15=0,0,D16/D15-1) -> -0.56735215 | I16: =AVERAGE(D14:D16) -> 30581900
A17: Tháng 12 | B17: 12 | C17: =COUNTIFS('Dữ liệu sạch'!$C$2:$C$201,$B17,'Dữ liệu sạch'!$R$2:$R$201,"Hoàn thành") -> 32 | D17: =SUMIFS('Dữ liệu sạch'!$W$2:$W$201,'Dữ liệu sạch'!$C$2:$C$201,$B17) -> 64569600 | E17: =SUMIFS('Dữ liệu sạch'!$X$2:$X$201,'Dữ liệu sạch'!$C$2:$C$201,$B17) -> 24499600 | F17: =IF(D17=0,0,E17/D17) -> 0.37942933 | G17: =IF(C17=0,0,D17/C17) -> 2017800 | H17: =IF(D16=0,0,D17/D16-1) -> 3.3005688 | I17: =AVERAGE(D15:D17) -> 38095617
A18: Cả năm | C18: =SUM(C6:C17) -> 176 | D18: =SUM(D6:D17) -> 346260650 | E18: =SUM(E6:E17) -> 131000650 | F18: =IF(D18=0,0,E18/D18) -> 0.37832959 | G18: =IF(C18=0,0,D18/C18) -> 1967390.1
A21: 2. Doanh thu theo quý
A22: Quý | B22: Số đơn hoàn thành | C22: Doanh thu (VNĐ) | D22: Lợi nhuận (VNĐ) | E22: Biên LN | F22: Tăng trưởng so quý trước | G22: Tỷ trọng doanh thu
A23: Q1 | B23: =COUNTIFS('Dữ liệu sạch'!$D$2:$D$201,$A23,'Dữ liệu sạch'!$R$2:$R$201,"Hoàn thành") -> 35 | C23: =SUMIFS('Dữ liệu sạch'!$W$2:$W$201,'Dữ liệu sạch'!$D$2:$D$201,$A23) -> 72692800 | D23: =SUMIFS('Dữ liệu sạch'!$X$2:$X$201,'Dữ liệu sạch'!$D$2:$D$201,$A23) -> 24432800 | E23: =IF(C23=0,0,D23/C23) -> 0.33611032 | F23: – | G23: =C23/$C$27 -> 0.20993665
A24: Q2 | B24: =COUNTIFS('Dữ liệu sạch'!$D$2:$D$201,$A24,'Dữ liệu sạch'!$R$2:$R$201,"Hoàn thành") -> 40 | C24: =SUMIFS('Dữ liệu sạch'!$W$2:$W$201,'Dữ liệu sạch'!$D$2:$D$201,$A24) -> 63565050 | D24: =SUMIFS('Dữ liệu sạch'!$X$2:$X$201,'Dữ liệu sạch'!$D$2:$D$201,$A24) -> 27235050 | E24: =IF(C24=0,0,D24/C24) -> 0.42845951 | F24: =IF(C23=0,0,C24/C23-1) -> -0.12556608 | G24: =C24/$C$27 -> 0.18357573
A25: Q3 | B25: =COUNTIFS('Dữ liệu sạch'!$D$2:$D$201,$A25,'Dữ liệu sạch'!$R$2:$R$201,"Hoàn thành") -> 44 | C25: =SUMIFS('Dữ liệu sạch'!$W$2:$W$201,'Dữ liệu sạch'!$D$2:$D$201,$A25) -> 95715950 | D25: =SUMIFS('Dữ liệu sạch'!$X$2:$X$201,'Dữ liệu sạch'!$D$2:$D$201,$A25) -> 35735950 | E25: =IF(C25=0,0,D25/C25) -> 0.37335418 | F25: =IF(C24=0,0,C25/C24-1) -> 0.50579524 | G25: =C25/$C$27 -> 0.27642745
A26: Q4 | B26: =COUNTIFS('Dữ liệu sạch'!$D$2:$D$201,$A26,'Dữ liệu sạch'!$R$2:$R$201,"Hoàn thành") -> 57 | C26: =SUMIFS('Dữ liệu sạch'!$W$2:$W$201,'Dữ liệu sạch'!$D$2:$D$201,$A26) -> 114286850 | D26: =SUMIFS('Dữ liệu sạch'!$X$2:$X$201,'Dữ liệu sạch'!$D$2:$D$201,$A26) -> 43596850 | E26: =IF(C26=0,0,D26/C26) -> 0.38146865 | F26: =IF(C25=0,0,C26/C25-1) -> 0.19402095 | G26: =C26/$C$27 -> 0.33006017
A27: Cả năm | B27: =SUM(B23:B26) -> 176 | C27: =SUM(C23:C26) -> 346260650 | D27: =SUM(D23:D26) -> 131000650 | E27: =IF(C27=0,0,D27/C27) -> 0.37832959 | G27: =SUM(G23:G26) -> 1
A30: 3. Doanh thu theo thứ trong tuần
A31: Thứ | B31: Mã thứ (1=T2) | C31: Số đơn hoàn thành | D31: Doanh thu (VNĐ) | E31: Tỷ trọng | F31: Doanh thu TB / đơn (VNĐ)
A32: Thứ 2 | B32: 1 | C32: =COUNTIFS('Dữ liệu sạch'!$Y$2:$Y$201,$B32,'Dữ liệu sạch'!$R$2:$R$201,"Hoàn thành") -> 26 | D32: =SUMIFS('Dữ liệu sạch'!$W$2:$W$201,'Dữ liệu sạch'!$Y$2:$Y$201,$B32) -> 50316850 | E32: =D32/$D$39 -> 0.14531495 | F32: =IF(C32=0,0,D32/C32) -> 1935263.5
A33: Thứ 3 | B33: 2 | C33: =COUNTIFS('Dữ liệu sạch'!$Y$2:$Y$201,$B33,'Dữ liệu sạch'!$R$2:$R$201,"Hoàn thành") -> 22 | D33: =SUMIFS('Dữ liệu sạch'!$W$2:$W$201,'Dữ liệu sạch'!$Y$2:$Y$201,$B33) -> 37562300 | E33: =D33/$D$39 -> 0.10847984 | F33: =IF(C33=0,0,D33/C33) -> 1707377.3
A34: Thứ 4 | B34: 3 | C34: =COUNTIFS('Dữ liệu sạch'!$Y$2:$Y$201,$B34,'Dữ liệu sạch'!$R$2:$R$201,"Hoàn thành") -> 25 | D34: =SUMIFS('Dữ liệu sạch'!$W$2:$W$201,'Dữ liệu sạch'!$Y$2:$Y$201,$B34) -> 53645700 | E34: =D34/$D$39 -> 0.15492866 | F34: =IF(C34=0,0,D34/C34) -> 2145828
A35: Thứ 5 | B35: 4 | C35: =COUNTIFS('Dữ liệu sạch'!$Y$2:$Y$201,$B35,'Dữ liệu sạch'!$R$2:$R$201,"Hoàn thành") -> 31 | D35: =SUMIFS('Dữ liệu sạch'!$W$2:$W$201,'Dữ liệu sạch'!$Y$2:$Y$201,$B35) -> 74583700 | E35: =D35/$D$39 -> 0.21539756 | F35: =IF(C35=0,0,D35/C35) -> 2405925.8
A36: Thứ 6 | B36: 5 | C36: =COUNTIFS('Dữ liệu sạch'!$Y$2:$Y$201,$B36,'Dữ liệu sạch'!$R$2:$R$201,"Hoàn thành") -> 26 | D36: =SUMIFS('Dữ liệu sạch'!$W$2:$W$201,'Dữ liệu sạch'!$Y$2:$Y$201,$B36) -> 60623800 | E36: =D36/$D$39 -> 0.1750814 | F36: =IF(C36=0,0,D36/C36) -> 2331684.6
A37: Thứ 7 | B37: 6 | C37: =COUNTIFS('Dữ liệu sạch'!$Y$2:$Y$201,$B37,'Dữ liệu sạch'!$R$2:$R$201,"Hoàn thành") -> 20 | D37: =SUMIFS('Dữ liệu sạch'!$W$2:$W$201,'Dữ liệu sạch'!$Y$2:$Y$201,$B37) -> 35486500 | E37: =D37/$D$39 -> 0.10248493 | F37: =IF(C37=0,0,D37/C37) -> 1774325
A38: Chủ nhật | B38: 7 | C38: =COUNTIFS('Dữ liệu sạch'!$Y$2:$Y$201,$B38,'Dữ liệu sạch'!$R$2:$R$201,"Hoàn thành") -> 26 | D38: =SUMIFS('Dữ liệu sạch'!$W$2:$W$201,'Dữ liệu sạch'!$Y$2:$Y$201,$B38) -> 34041800 | E38: =D38/$D$39 -> 0.098312644 | F38: =IF(C38=0,0,D38/C38) -> 1309300
A39: Tổng | C39: =SUM(C32:C38) -> 176 | D39: =SUM(D32:D38) -> 346260650 | E39: =SUM(E32:E38) -> 1 | F39: =IF(C39=0,0,D39/C39) -> 1967390.1
A42: 4. Dự báo tham khảo 3 tháng đầu năm sau (hồi quy tuyến tính)
A43: Tháng dự báo | B43: x (số tháng) | C43: Doanh thu dự báo (VNĐ)
A44: Tháng 1/2026 | B44: 13 | C44: =FORECAST(B44,$D$6:$D$17,$B$6:$B$17) -> 43265021
A45: Tháng 2/2026 | B45: 14 | C45: =FORECAST(B45,$D$6:$D$17,$B$6:$B$17) -> 45481939
A46: Tháng 3/2026 | B46: 15 | C46: =FORECAST(B46,$D$6:$D$17,$B$6:$B$17) -> 47698857
A47: R² của mô hình | C47: =RSQ(D6:D17,B6:B17) -> 0.22817829

Sheet PT Sản phẩm
A4: 1. Theo danh mục
A5: Danh mục | B5: Số đơn hoàn thành | C5: Số lượng bán | D5: Doanh thu (VNĐ) | E5: Tỷ trọng | F5: Lợi nhuận (VNĐ) | G5: Biên LN
A6: Điện tử | B6: =COUNTIFS('Dữ liệu sạch'!$J$2:$J$201,$A6,'Dữ liệu sạch'!$R$2:$R$201,"Hoàn thành") -> 41 | C6: =SUMIFS('Dữ liệu sạch'!$N$2:$N$201,'Dữ liệu sạch'!$J$2:$J$201,$A6,'Dữ liệu sạch'!$R$2:$R$201,"Hoàn thành") -> 101 | D6: =SUMIFS('Dữ liệu sạch'!$W$2:$W$201,'Dữ liệu sạch'!$J$2:$J$201,$A6) -> 100920800 | E6: =D6/$D$11 -> 0.29145905 | F6: =SUMIFS('Dữ liệu sạch'!$X$2:$X$201,'Dữ liệu sạch'!$J$2:$J$201,$A6) -> 33150800 | G6: =IF(D6=0,0,F6/D6) -> 0.32848333
A7: Gia dụng | B7: =COUNTIFS('Dữ liệu sạch'!$J$2:$J$201,$A7,'Dữ liệu sạch'!$R$2:$R$201,"Hoàn thành") -> 29 | C7: =SUMIFS('Dữ liệu sạch'!$N$2:$N$201,'Dữ liệu sạch'!$J$2:$J$201,$A7,'Dữ liệu sạch'!$R$2:$R$201,"Hoàn thành") -> 62 | D7: =SUMIFS('Dữ liệu sạch'!$W$2:$W$201,'Dữ liệu sạch'!$J$2:$J$201,$A7) -> 83303300 | E7: =D7/$D$11 -> 0.24057975 | F7: =SUMIFS('Dữ liệu sạch'!$X$2:$X$201,'Dữ liệu sạch'!$J$2:$J$201,$A7) -> 26883300 | G7: =IF(D7=0,0,F7/D7) -> 0.32271591
A8: Thời trang | B8: =COUNTIFS('Dữ liệu sạch'!$J$2:$J$201,$A8,'Dữ liệu sạch'!$R$2:$R$201,"Hoàn thành") -> 55 | C8: =SUMIFS('Dữ liệu sạch'!$N$2:$N$201,'Dữ liệu sạch'!$J$2:$J$201,$A8,'Dữ liệu sạch'!$R$2:$R$201,"Hoàn thành") -> 146 | D8: =SUMIFS('Dữ liệu sạch'!$W$2:$W$201,'Dữ liệu sạch'!$J$2:$J$201,$A8) -> 129392600 | E8: =D8/$D$11 -> 0.37368555 | F8: =SUMIFS('Dữ liệu sạch'!$X$2:$X$201,'Dữ liệu sạch'!$J$2:$J$201,$A8) -> 56562600 | G8: =IF(D8=0,0,F8/D8) -> 0.43713937
A9: Mỹ phẩm | B9: =COUNTIFS('Dữ liệu sạch'!$J$2:$J$201,$A9,'Dữ liệu sạch'!$R$2:$R$201,"Hoàn thành") -> 29 | C9: =SUMIFS('Dữ liệu sạch'!$N$2:$N$201,'Dữ liệu sạch'!$J$2:$J$201,$A9,'Dữ liệu sạch'!$R$2:$R$201,"Hoàn thành") -> 58 | D9: =SUMIFS('Dữ liệu sạch'!$W$2:$W$201,'Dữ liệu sạch'!$J$2:$J$201,$A9) -> 19240500 | E9: =D9/$D$11 -> 0.055566522 | F9: =SUMIFS('Dữ liệu sạch'!$X$2:$X$201,'Dữ liệu sạch'!$J$2:$J$201,$A9) -> 10010500 | G9: =IF(D9=0,0,F9/D9) -> 0.52028274
A10: Thực phẩm | B10: =COUNTIFS('Dữ liệu sạch'!$J$2:$J$201,$A10,'Dữ liệu sạch'!$R$2:$R$201,"Hoàn thành") -> 22 | C10: =SUMIFS('Dữ liệu sạch'!$N$2:$N$201,'Dữ liệu sạch'!$J$2:$J$201,$A10,'Dữ liệu sạch'!$R$2:$R$201,"Hoàn thành") -> 46 | D10: =SUMIFS('Dữ liệu sạch'!$W$2:$W$201,'Dữ liệu sạch'!$J$2:$J$201,$A10) -> 13403450 | E10: =D10/$D$11 -> 0.038709134 | F10: =SUMIFS('Dữ liệu sạch'!$X$2:$X$201,'Dữ liệu sạch'!$J$2:$J$201,$A10) -> 4393450 | G10: =IF(D10=0,0,F10/D10) -> 0.32778501
A11: Tổng | B11: =SUM(B6:B10) -> 176 | C11: =SUM(C6:C10) -> 413 | D11: =SUM(D6:D10) -> 346260650 | E11: =SUM(E6:E10) -> 1 | F11: =SUM(F6:F10) -> 131000650 | G11: =IF(D11=0,0,F11/D11) -> 0.37832959
A13: 2. Theo sản phẩm
A14: Sản phẩm | B14: Danh mục | C14: Số lượng bán | D14: Doanh thu (VNĐ) | E14: Lợi nhuận (VNĐ) | F14: Biên LN | G14: Điểm xếp hạng (cột phụ)
A15: Tai nghe Bluetooth | B15: Điện tử | C15: =SUMIFS('Dữ liệu sạch'!$N$2:$N$201,'Dữ liệu sạch'!$K$2:$K$201,$A15,'Dữ liệu sạch'!$R$2:$R$201,"Hoàn thành") -> 14 | D15: =SUMIFS('Dữ liệu sạch'!$W$2:$W$201,'Dữ liệu sạch'!$K$2:$K$201,$A15) -> 10812800 | E15: =SUMIFS('Dữ liệu sạch'!$X$2:$X$201,'Dữ liệu sạch'!$K$2:$K$201,$A15) -> 3532800 | F15: =IF(D15=0,0,E15/D15) -> 0.32672388 | G15: =D15+ROW()/1000000 -> 10812800
A16: Loa thông minh | B16: Điện tử | C16: =SUMIFS('Dữ liệu sạch'!$N$2:$N$201,'Dữ liệu sạch'!$K$2:$K$201,$A16,'Dữ liệu sạch'!$R$2:$R$201,"Hoàn thành") -> 25 | D16: =SUMIFS('Dữ liệu sạch'!$W$2:$W$201,'Dữ liệu sạch'!$K$2:$K$201,$A16) -> 42892500 | E16: =SUMIFS('Dữ liệu sạch'!$X$2:$X$201,'Dữ liệu sạch'!$K$2:$K$201,$A16) -> 12892500 | F16: =IF(D16=0,0,E16/D16) -> 0.30057702 | G16: =D16+ROW()/1000000 -> 42892500
A17: Bàn phím cơ | B17: Điện tử | C17: =SUMIFS('Dữ liệu sạch'!$N$2:$N$201,'Dữ liệu sạch'!$K$2:$K$201,$A17,'Dữ liệu sạch'!$R$2:$R$201,"Hoàn thành") -> 27 | D17: =SUMIFS('Dữ liệu sạch'!$W$2:$W$201,'Dữ liệu sạch'!$K$2:$K$201,$A17) -> 29013000 | E17: =SUMIFS('Dữ liệu sạch'!$X$2:$X$201,'Dữ liệu sạch'!$K$2:$K$201,$A17) -> 9573000 | F17: =IF(D17=0,0,E17/D17) -> 0.32995554 | G17: =D17+ROW()/1000000 -> 29013000
A18: Chuột không dây | B18: Điện tử | C18: =SUMIFS('Dữ liệu sạch'!$N$2:$N$201,'Dữ liệu sạch'!$K$2:$K$201,$A18,'Dữ liệu sạch'!$R$2:$R$201,"Hoàn thành") -> 22 | D18: =SUMIFS('Dữ liệu sạch'!$W$2:$W$201,'Dữ liệu sạch'!$K$2:$K$201,$A18) -> 9422800 | E18: =SUMIFS('Dữ liệu sạch'!$X$2:$X$201,'Dữ liệu sạch'!$K$2:$K$201,$A18) -> 3702800 | F18: =IF(D18=0,0,E18/D18) -> 0.39296175 | G18: =D18+ROW()/1000000 -> 9422800
A19: Sạc dự phòng 20000mAh | B19: Điện tử | C19: =SUMIFS('Dữ liệu sạch'!$N$2:$N$201,'Dữ liệu sạch'!$K$2:$K$201,$A19,'Dữ liệu sạch'!$R$2:$R$201,"Hoàn thành") -> 13 | D19: =SUMIFS('Dữ liệu sạch'!$W$2:$W$201,'Dữ liệu sạch'!$K$2:$K$201,$A19) -> 8779700 | E19: =SUMIFS('Dữ liệu sạch'!$X$2:$X$201,'Dữ liệu sạch'!$K$2:$K$201,$A19) -> 3449700 | F19: =IF(D19=0,0,E19/D19) -> 0.39291775 | G19: =D19+ROW()/1000000 -> 8779700
A20: Nồi chiên không dầu | B20: Gia dụng | C20: =SUMIFS('Dữ liệu sạch'!$N$2:$N$201,'Dữ liệu sạch'!$K$2:$K$201,$A20,'Dữ liệu sạch'!$R$2:$R$201,"Hoàn thành") -> 18 | D20: =SUMIFS('Dữ liệu sạch'!$W$2:$W$201,'Dữ liệu sạch'!$K$2:$K$201,$A20) -> 40296000 | E20: =SUMIFS('Dữ liệu sạch'!$X$2:$X$201,'Dữ liệu sạch'!$K$2:$K$201,$A20) -> 12396000 | F20: =IF(D20=0,0,E20/D20) -> 0.30762359 | G20: =D20+ROW()/1000000 -> 40296000
A21: Máy hút bụi mini | B21: Gia dụng | C21: =SUMIFS('Dữ liệu sạch'!$N$2:$N$201,'Dữ liệu sạch'!$K$2:$K$201,$A21,'Dữ liệu sạch'!$R$2:$R$201,"Hoàn thành") -> 14 | D21: =SUMIFS('Dữ liệu sạch'!$W$2:$W$201,'Dữ liệu sạch'!$K$2:$K$201,$A21) -> 20320000 | E21: =SUMIFS('Dữ liệu sạch'!$X$2:$X$201,'Dữ liệu sạch'!$K$2:$K$201,$A21) -> 6320000 | F21: =IF(D21=0,0,E21/D21) -> 0.31102362 | G21: =D21+ROW()/1000000 -> 20320000
A22: Ấm siêu tốc | B22: Gia dụng | C22: =SUMIFS('Dữ liệu sạch'!$N$2:$N$201,'Dữ liệu sạch'!$K$2:$K$201,$A22,'Dữ liệu sạch'!$R$2:$R$201,"Hoàn thành") -> 12 | D22: =SUMIFS('Dữ liệu sạch'!$W$2:$W$201,'Dữ liệu sạch'!$K$2:$K$201,$A22) -> 5738200 | E22: =SUMIFS('Dữ liệu sạch'!$X$2:$X$201,'Dữ liệu sạch'!$K$2:$K$201,$A22) -> 2018200 | F22: =IF(D22=0,0,E22/D22) -> 0.35171308 | G22: =D22+ROW()/1000000 -> 5738200
A23: Máy xay sinh tố | B23: Gia dụng | C23: =SUMIFS('Dữ liệu sạch'!$N$2:$N$201,'Dữ liệu sạch'!$K$2:$K$201,$A23,'Dữ liệu sạch'!$R$2:$R$201,"Hoàn thành") -> 18 | D23: =SUMIFS('Dữ liệu sạch'!$W$2:$W$201,'Dữ liệu sạch'!$K$2:$K$201,$A23) -> 16949100 | E23: =SUMIFS('Dữ liệu sạch'!$X$2:$X$201,'Dữ liệu sạch'!$K$2:$K$201,$A23) -> 6149100 | F23: =IF(D23=0,0,E23/D23) -> 0.36279802 | G23: =D23+ROW()/1000000 -> 16949100
A24: Áo thun nam | B24: Thời trang | C24: =SUMIFS('Dữ liệu sạch'!$N$2:$N$201,'Dữ liệu sạch'!$K$2:$K$201,$A24,'Dữ liệu sạch'!$R$2:$R$201,"Hoàn thành") -> 25 | D24: =SUMIFS('Dữ liệu sạch'!$W$2:$W$201,'Dữ liệu sạch'!$K$2:$K$201,$A24) -> 6563200 | E24: =SUMIFS('Dữ liệu sạch'!$X$2:$X$201,'Dữ liệu sạch'!$K$2:$K$201,$A24) -> 3313200 | F24: =IF(D24=0,0,E24/D24) -> 0.50481472 | G24: =D24+ROW()/1000000 -> 6563200
A25: Giày thể thao | B25: Thời trang | C25: =SUMIFS('Dữ liệu sạch'!$N$2:$N$201,'Dữ liệu sạch'!$K$2:$K$201,$A25,'Dữ liệu sạch'!$R$2:$R$201,"Hoàn thành") -> 26 | D25: =SUMIFS('Dữ liệu sạch'!$W$2:$W$201,'Dữ liệu sạch'!$K$2:$K$201,$A25) -> 37222500 | E25: =SUMIFS('Dữ liệu sạch'!$X$2:$X$201,'Dữ liệu sạch'!$K$2:$K$201,$A25) -> 16422500 | F25: =IF(D25=0,0,E25/D25) -> 0.4411982 | G25: =D25+ROW()/1000000 -> 37222500
A26: Túi xách nữ | B26: Thời trang | C26: =SUMIFS('Dữ liệu sạch'!$N$2:$N$201,'Dữ liệu sạch'!$K$2:$K$201,$A26,'Dữ liệu sạch'!$R$2:$R$201,"Hoàn thành") -> 51 | D26: =SUMIFS('Dữ liệu sạch'!$W$2:$W$201,'Dữ liệu sạch'!$K$2:$K$201,$A26) -> 55785000 | E26: =SUMIFS('Dữ liệu sạch'!$X$2:$X$201,'Dữ liệu sạch'!$K$2:$K$201,$A26) -> 24165000 | F26: =IF(D26=0,0,E26/D26) -> 0.43318096 | G26: =D26+ROW()/1000000 -> 55785000
... A33: Hạt dinh dưỡng mix | B33: Thực phẩm | C33: =SUMIFS('Dữ liệu sạch'!$N$2:$N$201,'Dữ liệu sạch'!$K$2:$K$201,$A33,'Dữ liệu sạch'!$R$2:$R$201,"Hoàn thành") -> 18 | D33: =SUMIFS('Dữ liệu sạch'!$W$2:$W$201,'Dữ liệu sạch'!$K$2:$K$201,$A33) -> 5771500 | E33: =SUMIFS('Dữ liệu sạch'!$X$2:$X$201,'Dữ liệu sạch'!$K$2:$K$201,$A33) -> 1811500 | F33: =IF(D33=0,0,E33/D33) -> 0.31386988 | G33: =D33+ROW()/1000000 -> 5771500
A34: Tổng | C34: =SUM(C15:C33) -> 413 | D34: =SUM(D15:D33) -> 346260650 | E34: =SUM(E15:E33) -> 131000650 | F34: =IF(D34=0,0,E34/D34) -> 0.37832959
A36: 3. Top 10 sản phẩm theo doanh thu (xếp hạng tự động bằng LARGE/INDEX/MATCH) và phân tích Pareto
A37: Hạng | B37: Sản phẩm | C37: Doanh thu (VNĐ) | D37: Tỷ trọng | E37: Lũy kế tỷ trọng | F37: Biên LN | G37: Dòng (cột phụ)
A38: 1 | B38: =INDEX($A$15:$A$33,G38) -> Túi xách nữ | C38: =INDEX($D$15:$D$33,G38) -> 55785000 | D38: =C38/$D$34 -> 0.16110696 | E38: =SUM($D$38:D38) -> 0.16110696 | F38: =INDEX($F$15:$F$33,G38) -> 0.43318096 | G38: =MATCH(LARGE($G$15:$G$33,A38),$G$15:$G$33,0) -> 12
A39: 2 | B39: =INDEX($A$15:$A$33,G39) -> Loa thông minh | C39: =INDEX($D$15:$D$33,G39) -> 42892500 | D39: =C39/$D$34 -> 0.12387345 | E39: =SUM($D$38:D39) -> 0.2849804 | F39: =INDEX($F$15:$F$33,G39) -> 0.30057702 | G39: =MATCH(LARGE($G$15:$G$33,A39),$G$15:$G$33,0) -> 2
A40: 3 | B40: =INDEX($A$15:$A$33,G40) -> Nồi chiên không dầu | C40: =INDEX($D$15:$D$33,G40) -> 40296000 | D40: =C40/$D$34 -> 0.11637476 | E40: =SUM($D$38:D40) -> 0.40135516 | F40: =INDEX($F$15:$F$33,G40) -> 0.30762359 | G40: =MATCH(LARGE($G$15:$G$33,A40),$G$15:$G$33,0) -> 6
A41: 4 | B41: =INDEX($A$15:$A$33,G41) -> Giày thể thao | C41: =INDEX($D$15:$D$33,G41) -> 37222500 | D41: =C41/$D$34 -> 0.1074985 | E41: =SUM($D$38:D41) -> 0.50885366 | F41: =INDEX($F$15:$F$33,G41) -> 0.4411982 | G41: =MATCH(LARGE($G$15:$G$33,A41),$G$15:$G$33,0) -> 11
A42: 5 | B42: =INDEX($A$15:$A$33,G42) -> Áo khoác gió | C42: =INDEX($D$15:$D$33,G42) -> 29821900 | D42: =C42/$D$34 -> 0.086125582 | E42: =SUM($D$38:D42) -> 0.59497924 | F42: =INDEX($F$15:$F$33,G42) -> 0.42458395 | G42: =MATCH(LARGE($G$15:$G$33,A42),$G$15:$G$33,0) -> 13
A43: 6 | B43: =INDEX($A$15:$A$33,G43) -> Bàn phím cơ | C43: =INDEX($D$15:$D$33,G43) -> 29013000 | D43: =C43/$D$34 -> 0.083789481 | E43: =SUM($D$38:D43) -> 0.67876873 | F43: =INDEX($F$15:$F$33,G43) -> 0.32995554 | G43: =MATCH(LARGE($G$15:$G$33,A43),$G$15:$G$33,0) -> 3
A44: 7 | B44: =INDEX($A$15:$A$33,G44) -> Máy hút bụi mini | C44: =INDEX($D$15:$D$33,G44) -> 20320000 | D44: =C44/$D$34 -> 0.058684116 | E44: =SUM($D$38:D44) -> 0.73745284 | F44: =INDEX($F$15:$F$33,G44) -> 0.31102362 | G44: =MATCH(LARGE($G$15:$G$33,A44),$G$15:$G$33,0) -> 7
A45: 8 | B45: =INDEX($A$15:$A$33,G45) -> Máy xay sinh tố | C45: =INDEX($D$15:$D$33,G45) -> 16949100 | D45: =C45/$D$34 -> 0.048948964 | E45: =SUM($D$38:D45) -> 0.7864018 | F45: =INDEX($F$15:$F$33,G45) -> 0.36279802 | G45: =MATCH(LARGE($G$15:$G$33,A45),$G$15:$G$33,0) -> 9
A46: 9 | B46: =INDEX($A$15:$A$33,G46) -> Tai nghe Bluetooth | C46: =INDEX($D$15:$D$33,G46) -> 10812800 | D46: =C46/$D$34 -> 0.031227343 | E46: =SUM($D$38:D46) -> 0.81762915 | F46: =INDEX($F$15:$F$33,G46) -> 0.32672388 | G46: =MATCH(LARGE($G$15:$G$33,A46),$G$15:$G$33,0) -> 1
A47: 10 | B47: =INDEX($A$15:$A$33,G47) -> Chuột không dây | C47: =INDEX($D$15:$D$33,G47) -> 9422800 | D47: =C47/$D$34 -> 0.027213026 | E47: =SUM($D$38:D47) -> 0.84484217 | F47: =INDEX($F$15:$F$33,G47) -> 0.39296175 | G47: =MATCH(LARGE($G$15:$G$33,A47),$G$15:$G$33,0) -> 4
A49: 4. Ảnh hưởng của mức giảm giá đến doanh thu và biên lợi nhuận
A50: Mức giảm giá | B50: Số đơn hoàn thành | C50: Doanh thu (VNĐ) | D50: Lợi nhuận (VNĐ) | E50: Biên LN | F50: Số lượng TB / đơn
A51: 0 | B51: =COUNTIFS('Dữ liệu sạch'!$P$2:$P$201,$A51,'Dữ liệu sạch'!$R$2:$R$201,"Hoàn thành") -> 62 | C51: =SUMIFS('Dữ liệu sạch'!$W$2:$W$201,'Dữ liệu sạch'!$P$2:$P$201,$A51) -> 119101000 | D51: =SUMIFS('Dữ liệu sạch'!$X$2:$X$201,'Dữ liệu sạch'!$P$2:$P$201,$A51) -> 51901000 | E51: =IF(C51=0,0,D51/C51) -> 0.435773 | F51: =IF(B51=0,0,SUMIFS('Dữ liệu sạch'!$N$2:$N$201,'Dữ liệu sạch'!$P$2:$P$201,$A51,'Dữ liệu sạch'!$R$2:$R$201,"Hoàn thành")/B51) -> 2.1290323
A52: 0.05 | B52: =COUNTIFS('Dữ liệu sạch'!$P$2:$P$201,$A52,'Dữ liệu sạch'!$R$2:$R$201,"Hoàn thành") -> 37 | C52: =SUMIFS('Dữ liệu sạch'!$W$2:$W$201,'Dữ liệu sạch'!$P$2:$P$201,$A52) -> 59884200 | D52: =SUMIFS('Dữ liệu sạch'!$X$2:$X$201,'Dữ liệu sạch'!$P$2:$P$201,$A52) -> 23744200 | E52: =IF(C52=0,0,D52/C52) -> 0.39650192 | F52: =IF(B52=0,0,SUMIFS('Dữ liệu sạch'!$N$2:$N$201,'Dữ liệu sạch'!$P$2:$P$201,$A52,'Dữ liệu sạch'!$R$2:$R$201,"Hoàn thành")/B52) -> 2.2972973
...

Sheet PT Khu vực - Kênh
A4: 1. Theo khu vực
A5: Khu vực | B5: Số đơn hoàn thành | C5: Doanh thu (VNĐ) | D5: Tỷ trọng | E5: Lợi nhuận (VNĐ) | F5: Biên LN | G5: Giá trị đơn TB (VNĐ)
A6: Miền Bắc | B6: =COUNTIFS('Dữ liệu sạch'!$H$2:$H$201,$A6,'Dữ liệu sạch'!$R$2:$R$201,"Hoàn thành") -> 81 | C6: =SUMIFS('Dữ liệu sạch'!$W$2:$W$201,'Dữ liệu sạch'!$H$2:$H$201,$A6) -> 146116400 | D6: =C6/$C$9 -> 0.42198384 | E6: =SUMIFS('Dữ liệu sạch'!$X$2:$X$201,'Dữ liệu sạch'!$H$2:$H$201,$A6) -> 54486400 | F6: =IF(C6=0,0,E6/C6) -> 0.37289722 | G6: =IF(B6=0,0,C6/B6) -> 1803906.2
A7: Miền Trung | B7: =COUNTIFS('Dữ liệu sạch'!$H$2:$H$201,$A7,'Dữ liệu sạch'!$R$2:$R$201,"Hoàn thành") -> 23 | C7: =SUMIFS('Dữ liệu sạch'!$W$2:$W$201,'Dữ liệu sạch'!$H$2:$H$201,$A7) -> 41500500 | D7: =C7/$C$9 -> 0.11985335 | E7: =SUMIFS('Dữ liệu sạch'!$X$2:$X$201,'Dữ liệu sạch'!$H$2:$H$201,$A7) -> 15890500 | F7: =IF(C7=0,0,E7/C7) -> 0.382899 | G7: =IF(B7=0,0,C7/B7) -> 1804369.6
A8: Miền Nam | B8: =COUNTIFS('Dữ liệu sạch'!$H$2:$H$201,$A8,'Dữ liệu sạch'!$R$2:$R$201,"Hoàn thành") -> 72 | C8: =SUMIFS('Dữ liệu sạch'!$W$2:$W$201,'Dữ liệu sạch'!$H$2:$H$201,$A8) -> 158643750 | D8: =C8/$C$9 -> 0.4581628 | E8: =SUMIFS('Dữ liệu sạch'!$X$2:$X$201,'Dữ liệu sạch'!$H$2:$H$201,$A8) -> 60623750 | F8: =IF(C8=0,0,E8/C8) -> 0.38213765 | G8: =IF(B8=0,0,C8/B8) -> 2203385.4
A9: Tổng | B9: =SUM(B6:B8) -> 176 | C9: =SUM(C6:C8) -> 346260650 | D9: =SUM(D6:D8) -> 1 | E9: =SUM(E6:E8) -> 131000650 | F9: =IF(C9=0,0,E9/C9) -> 0.37832959 | G9: =IF(B9=0,0,C9/B9) -> 1967390.1
A12: 2. Theo tỉnh/thành phố
A13: Tỉnh/Thành | B13: Khu vực | C13: Số đơn hoàn thành | D13: Doanh thu (VNĐ) | E13: Tỷ trọng | F13: Lợi nhuận (VNĐ) | G13: Biên LN
A14: Hà Nội | B14: Miền Bắc | C14: =COUNTIFS('Dữ liệu sạch'!$I$2:$I$201,$A14,'Dữ liệu sạch'!$R$2:$R$201,"Hoàn thành") -> 8 | D14: =SUMIFS('Dữ liệu sạch'!$W$2:$W$201,'Dữ liệu sạch'!$I$2:$I$201,$A14) -> 17910400 | E14: =D14/$D$26 -> 0.051725196 | F14: =SUMIFS('Dữ liệu sạch'!$X$2:$X$201,'Dữ liệu sạch'!$I$2:$I$201,$A14) -> 5790400 | G14: =IF(D14=0,0,F14/D14) -> 0.3232982
A15: Hải Phòng | B15: Miền Bắc | C15: =COUNTIFS('Dữ liệu sạch'!$I$2:$I$201,$A15,'Dữ liệu sạch'!$R$2:$R$201,"Hoàn thành") -> 8 | D15: =SUMIFS('Dữ liệu sạch'!$W$2:$W$201,'Dữ liệu sạch'!$I$2:$I$201,$A15) -> 12147000 | E15: =D15/$D$26 -> 0.035080509 | F15: =SUMIFS('Dữ liệu sạch'!$X$2:$X$201,'Dữ liệu sạch'!$I$2:$I$201,$A15) -> 5107000 | G15: =IF(D15=0,0,F15/D15) -> 0.42043303
A16: Bắc Ninh | B16: Miền Bắc | C16: =COUNTIFS('Dữ liệu sạch'!$I$2:$I$201,$A16,'Dữ liệu sạch'!$R$2:$R$201,"Hoàn thành") -> 37 | D16: =SUMIFS('Dữ liệu sạch'!$W$2:$W$201,'Dữ liệu sạch'!$I$2:$I$201,$A16) -> 72810950 | E16: =D16/$D$26 -> 0.21027786 | F16: =SUMIFS('Dữ liệu sạch'!$X$2:$X$201,'Dữ liệu sạch'!$I$2:$I$201,$A16) -> 28190950 | G16: =IF(D16=0,0,F16/D16) -> 0.38718009
A17: Quảng Ninh | B17: Miền Bắc | C17: =COUNTIFS('Dữ liệu sạch'!$I$2:$I$201,$A17,'Dữ liệu sạch'!$R$2:$R$201,"Hoàn thành") -> 28 | D17: =SUMIFS('Dữ liệu sạch'!$W$2:$W$201,'Dữ liệu sạch'!$I$2:$I$201,$A17) -> 43248050 | E17: =D17/$D$26 -> 0.12490027 | F17: =SUMIFS('Dữ liệu sạch'!$X$2:$X$201,'Dữ liệu sạch'!$I$2:$I$201,$A17) -> 15398050 | G17: =IF(D17=0,0,F17/D17) -> 0.35604033
A18: Đà Nẵng | B18: Miền Trung | C18: =COUNTIFS('Dữ liệu sạch'!$I$2:$I$201,$A18,'Dữ liệu sạch'!$R$2:$R$201,"Hoàn thành") -> 3 | D18: =SUMIFS('Dữ liệu sạch'!$W$2:$W$201,'Dữ liệu sạch'!$I$2:$I$201,$A18) -> 6750000 | E18: =D18/$D$26 -> 0.019493985 | F18: =SUMIFS('Dữ liệu sạch'!$X$2:$X$201,'Dữ liệu sạch'!$I$2:$I$201,$A18) -> 2420000 | G18: =IF(D18=0,0,F18/D18) -> 0.35851852
A19: Huế | B19: Miền Trung | C19: =COUNTIFS('Dữ liệu sạch'!$I$2:$I$201,$A19,'Dữ liệu sạch'!$R$2:$R$201,"Hoàn thành") -> 6 | D19: =SUMIFS('Dữ liệu sạch'!$W$2:$W$201,'Dữ liệu sạch'!$I$2:$I$201,$A19) -> 15525000 | E19: =D19/$D$26 -> 0.044836166 | F19: =SUMIFS('Dữ liệu sạch'!$X$2:$X$201,'Dữ liệu sạch'!$I$2:$I$201,$A19) -> 6035000 | G19: =IF(D19=0,0,F19/D19) -> 0.38872786
A20: Nghệ An | B20: Miền Trung | C20: =COUNTIFS('Dữ liệu sạch'!$I$2:$I$201,$A20,'Dữ liệu sạch'!$R$2:$R$201,"Hoàn thành") -> 4 | D20: =SUMIFS('Dữ liệu sạch'!$W$2:$W$201,'Dữ liệu sạch'!$I$2:$I$201,$A20) -> 6455500 | E20: =D20/$D$26 -> 0.01864347 | F20: =SUMIFS('Dữ liệu sạch'!$X$2:$X$201,'Dữ liệu sạch'!$I$2:$I$201,$A20) -> 2515500 | G20: =IF(D20=0,0,F20/D20) -> 0.38966773
A21: Khánh Hòa | B21: Miền Trung | C21: =COUNTIFS('Dữ liệu sạch'!$I$2:$I$201,$A21,'Dữ liệu sạch'!$R$2:$R$201,"Hoàn thành") -> 10 | D21: =SUMIFS('Dữ liệu sạch'!$W$2:$W$201,'Dữ liệu sạch'!$I$2:$I$201,$A21) -> 12770000 | E21: =D21/$D$26 -> 0.036879732 | F21: =SUMIFS('Dữ liệu sạch'!$X$2:$X$201,'Dữ liệu sạch'!$I$2:$I$201,$A21) -> 4920000 | G21: =IF(D21=0,0,F21/D21) -> 0.385278
A22: TP. Hồ Chí Minh | B22: Miền Nam | C22: =COUNTIFS('Dữ liệu sạch'!$I$2:$I$201,$A22,'Dữ liệu sạch'!$R$2:$R$201,"Hoàn thành") -> 11 | D22: =SUMIFS('Dữ liệu sạch'!$W$2:$W$201,'Dữ liệu sạch'!$I$2:$I$201,$A22) -> 26926950 | E22: =D22/$D$26 -> 0.077764973 | F22: =SUMIFS('Dữ liệu sạch'!$X$2:$X$201,'Dữ liệu sạch'!$I$2:$I$201,$A22) -> 11476950 | G22: =IF(D22=0,0,F22/D22) -> 0.4262254
A23: Cần Thơ | B23: Miền Nam | C23: =COUNTIFS('Dữ liệu sạch'!$I$2:$I$201,$A23,'Dữ liệu sạch'!$R$2:$R$201,"Hoàn thành") -> 22 | D23: =SUMIFS('Dữ liệu sạch'!$W$2:$W$201,'Dữ liệu sạch'!$I$2:$I$201,$A23) -> 43702100 | E23: =D23/$D$26 -> 0.12621157 | F23: =SUMIFS('Dữ liệu sạch'!$X$2:$X$201,'Dữ liệu sạch'!$I$2:$I$201,$A23) -> 16622100 | G23: =IF(D23=0,0,F23/D23) -> 0.38035014
A24: Bình Dương | B24: Miền Nam | C24: =COUNTIFS('Dữ liệu sạch'!$I$2:$I$201,$A24,'Dữ liệu sạch'!$R$2:$R$201,"Hoàn thành") -> 31 | D24: =SUMIFS('Dữ liệu sạch'!$W$2:$W$201,'Dữ liệu sạch'!$I$2:$I$201,$A24) -> 73291300 | E24: =D24/$D$26 -> 0.21166511 | F24: =SUMIFS('Dữ liệu sạch'!$X$2:$X$201,'Dữ liệu sạch'!$I$2:$I$201,$A24) -> 25761300 | G24: =IF(D24=0,0,F24/D24) -> 0.35149192
